Workbook
Name ValidWorkPackageNames: 'WORK PACKAGES'!$D$2:$D$100
Name ValidWorkPackageIDs: 'WORK PACKAGES'!$A$2:$A$100

Sheet DASHBOARD
A1: PROJECT PROGRESS DASHBOARD
A2: Work Package ID | B2: Package Code | C2: Priority Level | D2: Critical Path? | E2: Eng Completion | F2: Program Completion | G2: Conduit & Wire Pulls | H2: Devices Installed | I2: PreComm Completed | J2: BLOCKED - Eng Info | K2: BLOCKED - Vendor Info | L2: BLOCKED - Cond & Wire | M2: BLOCKED - Devices | N2: BLOCKED - PreComm | O2: Active Change Orders? | P2: Internal Gates Complete? | Q2: Open Punchlist Items | R2: Open RFIs | S2: Open Issues | T2: Weekly Notes | U2: Engineering Scope / Scope of Work
B3: =IF($A3="","",IFERROR(IF(INDEX('WORK PACKAGES'!$B$2:$B$100,MATCH($A3,'WORK PACKAGES'!$A$2:$A$100,0))="","",INDEX('WORK PACKAGES'!$B$2:$B$100,MATCH($A3,'WORK PACKAGES'!$A$2:$A$100,0))),"")) | C3: =IF($A3="","",IFERROR(IF(INDEX('WORK PACKAGES'!$E$2:$E$100,MATCH($A3,'WORK PACKAGES'!$A$2:$A$100,0))="","",INDEX('WORK PACKAGES'!$E$2:$E$100,MATCH($A3,'WORK PACKAGES'!$A$2:$A$100,0))),"")) | E3: =IF($A3="","",IFERROR(IF(INDEX('WP PROGRESS'!$F$2:$F$100,MATCH($A3,'WP PROGRESS'!$A$2:$A$100,0))="","",INDEX('WP PROGRESS'!$F$2:$F$100,MATCH($A3,'WP PROGRESS'!$A$2:$A$100,0))),"")) | F3: =IF($A3="","",IFERROR(IF(INDEX('WP PROGRESS'!$G$2:$G$100,MATCH($A3,'WP PROGRESS'!$A$2:$A$100,0))="","",INDEX('WP PROGRESS'!$G$2:$G$100,MATCH($A3,'WP PROGRESS'!$A$2:$A$100,0))),"")) | G3: =IF($A3="","",IFERROR(IF(INDEX('WP PROGRESS'!$H$2:$H$100,MATCH($A3,'WP PROGRESS'!$A$2:$A$100,0))="","",INDEX('WP PROGRESS'!$H$2:$H$100,MATCH($A3,'WP PROGRESS'!$A$2:$A$100,0))),"")) | H3: =IF($A3="","",IFERROR(IF(INDEX('WP PROGRESS'!$I$2:$I$100,MATCH($A3,'WP PROGRESS'!$A$2:$A$100,0))="","",INDEX('WP PROGRESS'!$I$2:$I$100,MATCH($A3,'WP PROGRESS'!$A$2:$A$100,0))),"")) | I3: =IF($A3="","",IFERROR(IF(INDEX('WP PROGRESS'!$K$2:$K$100,MATCH($A3,'WP PROGRESS'!$A$2:$A$100,0))="","",INDEX('WP PROGRESS'!$K$2:$K$100,MATCH($A3,'WP PROGRESS'!$A$2:$A$100,0))),"")) | P3: =IF($A3="","",IFERROR(IF(INDEX('WP PROGRESS'!$V$2:$V$100,MATCH($A3,'WP PROGRESS'!$A$2:$A$100,0))="","",INDEX('WP PROGRESS'!$V$2:$V$100,MATCH($A3,'WP PROGRESS'!$A$2:$A$100,0))),"")) | Q3: =IF($A3="","",IFERROR(IF(INDEX('WP PROGRESS'!$E$2:$E$100,MATCH($A3,'WP PROGRESS'!$A$2:$A$100,0))="","",INDEX('WP PROGRESS'!$E$2:$E$100,MATCH($A3,'WP PROGRESS'!$A$2:$A$100,0))),"")) | R3: =IF($A3="","",IFERROR(IF(INDEX('WP PROGRESS'!$Z$2:$Z$100,MATCH($A3,'WP PROGRESS'!$A$2:$A$100,0))="","",INDEX('WP PROGRESS'!$Z$2:$Z$100,MATCH($A3,'WP PROGRESS'!$A$2:$A$100,0))),"")) | S3: =IF($A3="","",COUNTIFS(ISSUES!$P$5:$P$200,"*"&$A3&"*",ISSUES!$H$5:$H$200,"<>Closed",ISSUES!$H$5:$H$200,"<>Resolved",ISSUES!$H$5:$H$200,"<>Cancelled",ISSUES!$H$5:$H$200,"<>",ISSUES!$A$5:$A$200,"<>")) | U3: =IF($A3="","",IFERROR(IF(INDEX('WORK PACKAGES'!$G$2:$G$100,MATCH($A3,'WORK PACKAGES'!$A$2:$A$100,0))="","",INDEX('WORK PACKAGES'!$G$2:$G$100,MATCH($A3,'WORK PACKAGES'!$A$2:$A$100,0))),""))
B4: =IF($A4="","",IFERROR(IF(INDEX('WORK PACKAGES'!$B$2:$B$100,MATCH($A4,'WORK PACKAGES'!$A$2:$A$100,0))="","",INDEX('WORK PACKAGES'!$B$2:$B$100,MATCH($A4,'WORK PACKAGES'!$A$2:$A$100,0))),"")) | C4: =IF($A4="","",IFERROR(IF(INDEX('WORK PACKAGES'!$E$2:$E$100,MATCH($A4,'WORK PACKAGES'!$A$2:$A$100,0))="","",INDEX('WORK PACKAGES'!$E$2:$E$100,MATCH($A4,'WORK PACKAGES'!$A$2:$A$100,0))),"")) | E4: =IF($A4="","",IFERROR(IF(INDEX('WP PROGRESS'!$F$2:$F$100,MATCH($A4,'WP PROGRESS'!$A$2:$A$100,0))="","",INDEX('WP PROGRESS'!$F$2:$F$100,MATCH($A4,'WP PROGRESS'!$A$2:$A$100,0))),"")) | F4: =IF($A4="","",IFERROR(IF(INDEX('WP PROGRESS'!$G$2:$G$100,MATCH($A4,'WP PROGRESS'!$A$2:$A$100,0))="","",INDEX('WP PROGRESS'!$G$2:$G$100,MATCH($A4,'WP PROGRESS'!$A$2:$A$100,0))),"")) | G4: =IF($A4="","",IFERROR(IF(INDEX('WP PROGRESS'!$H$2:$H$100,MATCH($A4,'WP PROGRESS'!$A$2:$A$100,0))="","",INDEX('WP PROGRESS'!$H$2:$H$100,MATCH($A4,'WP PROGRESS'!$A$2:$A$100,0))),"")) | H4: =IF($A4="","",IFERROR(IF(INDEX('WP PROGRESS'!$I$2:$I$100,MATCH($A4,'WP PROGRESS'!$A$2:$A$100,0))="","",INDEX('WP PROGRESS'!$I$2:$I$100,MATCH($A4,'WP PROGRESS'!$A$2:$A$100,0))),"")) | I4: =IF($A4="","",IFERROR(IF(INDEX('WP PROGRESS'!$K$2:$K$100,MATCH($A4,'WP PROGRESS'!$A$2:$A$100,0))="","",INDEX('WP PROGRESS'!$K$2:$K$100,MATCH($A4,'WP PROGRESS'!$A$2:$A$100,0))),"")) | P4: =IF($A4="","",IFERROR(IF(INDEX('WP PROGRESS'!$V$2:$V$100,MATCH($A4,'WP PROGRESS'!$A$2:$A$100,0))="","",INDEX('WP PROGRESS'!$V$2:$V$100,MATCH($A4,'WP PROGRESS'!$A$2:$A$100,0))),"")) | Q4: =IF($A4="","",IFERROR(IF(INDEX('WP PROGRESS'!$E$2:$E$100,MATCH($A4,'WP PROGRESS'!$A$2:$A$100,0))="","",INDEX('WP PROGRESS'!$E$2:$E$100,MATCH($A4,'WP PROGRESS'!$A$2:$A$100,0))),"")) | R4: =IF($A4="","",IFERROR(IF(INDEX('WP PROGRESS'!$Z$2:$Z$100,MATCH($A4,'WP PROGRESS'!$A$2:$A$100,0))="","",INDEX('WP PROGRESS'!$Z$2:$Z$100,MATCH($A4,'WP PROGRESS'!$A$2:$A$100,0))),"")) | S4: =IF($A4="","",COUNTIFS(ISSUES!$P$5:$P$200,"*"&$A4&"*",ISSUES!$H$5:$H$200,"<>Closed",ISSUES!$H$5:$H$200,"<>Resolved",ISSUES!$H$5:$H$200,"<>Cancelled",ISSUES!$H$5:$H$200,"<>",ISSUES!$A$5:$A$200,"<>")) | U4: =IF($A4="","",IFERROR(IF(INDEX('WORK PACKAGES'!$G$2:$G$100,MATCH($A4,'WORK PACKAGES'!$A$2:$A$100,0))="","",INDEX('WORK PACKAGES'!$G$2:$G$100,MATCH($A4,'WORK PACKAGES'!$A$2:$A$100,0))),""))
B5: =IF($A5="","",IFERROR(IF(INDEX('WORK PACKAGES'!$B$2:$B$100,MATCH($A5,'WORK PACKAGES'!$A$2:$A$100,0))="","",INDEX('WORK PACKAGES'!$B$2:$B$100,MATCH($A5,'WORK PACKAGES'!$A$2:$A$100,0))),"")) | C5: =IF($A5="","",IFERROR(IF(INDEX('WORK PACKAGES'!$E$2:$E$100,MATCH($A5,'WORK PACKAGES'!$A$2:$A$100,0))="","",INDEX('WORK PACKAGES'!$E$2:$E$100,MATCH($A5,'WORK PACKAGES'!$A$2:$A$100,0))),"")) | E5: =IF($A5="","",IFERROR(IF(INDEX('WP PROGRESS'!$F$2:$F$100,MATCH($A5,'WP PROGRESS'!$A$2:$A$100,0))="","",INDEX('WP PROGRESS'!$F$2:$F$100,MATCH($A5,'WP PROGRESS'!$A$2:$A$100,0))),"")) | F5: =IF($A5="","",IFERROR(IF(INDEX('WP PROGRESS'!$G$2:$G$100,MATCH($A5,'WP PROGRESS'!$A$2:$A$100,0))="","",INDEX('WP PROGRESS'!$G$2:$G$100,MATCH($A5,'WP PROGRESS'!$A$2:$A$100,0))),"")) | G5: =IF($A5="","",IFERROR(IF(INDEX('WP PROGRESS'!$H$2:$H$100,MATCH($A5,'WP PROGRESS'!$A$2:$A$100,0))="","",INDEX('WP PROGRESS'!$H$2:$H$100,MATCH($A5,'WP PROGRESS'!$A$2:$A$100,0))),"")) | H5: =IF($A5="","",IFERROR(IF(INDEX('WP PROGRESS'!$I$2:$I$100,MATCH($A5,'WP PROGRESS'!$A$2:$A$100,0))="","",INDEX('WP PROGRESS'!$I$2:$I$100,MATCH($A5,'WP PROGRESS'!$A$2:$A$100,0))),"")) | I5: =IF($A5="","",IFERROR(IF(INDEX('WP PROGRESS'!$K$2:$K$100,MATCH($A5,'WP PROGRESS'!$A$2:$A$100,0))="","",INDEX('WP PROGRESS'!$K$2:$K$100,MATCH($A5,'WP PROGRESS'!$A$2:$A$100,0))),"")) | P5: =IF($A5="","",IFERROR(IF(INDEX('WP PROGRESS'!$V$2:$V$100,MATCH($A5,'WP PROGRESS'!$A$2:$A$100,0))="","",INDEX('WP PROGRESS'!$V$2:$V$100,MATCH($A5,'WP PROGRESS'!$A$2:$A$100,0))),"")) | Q5: =IF($A5="","",IFERROR(IF(INDEX('WP PROGRESS'!$E$2:$E$100,MATCH($A5,'WP PROGRESS'!$A$2:$A$100,0))="","",INDEX('WP PROGRESS'!$E$2:$E$100,MATCH($A5,'WP PROGRESS'!$A$2:$A$100,0))),"")) | R5: =IF($A5="","",IFERROR(IF(INDEX('WP PROGRESS'!$Z$2:$Z$100,MATCH($A5,'WP PROGRESS'!$A$2:$A$100,0))="","",INDEX('WP PROGRESS'!$Z$2:$Z$100,MATCH($A5,'WP PROGRESS'!$A$2:$A$100,0))),"")) | S5: =IF($A5="","",COUNTIFS(ISSUES!$P$5:$P$200,"*"&$A5&"*",ISSUES!$H$5:$H$200,"<>Closed",ISSUES!$H$5:$H$200,"<>Resolved",ISSUES!$H$5:$H$200,"<>Cancelled",ISSUES!$H$5:$H$200,"<>",ISSUES!$A$5:$A$200,"<>")) | U5: =IF($A5="","",IFERROR(IF(INDEX('WORK PACKAGES'!$G$2:$G$100,MATCH($A5,'WORK PACKAGES'!$A$2:$A$100,0))="","",INDEX('WORK PACKAGES'!$G$2:$G$100,MATCH($A5,'WORK PACKAGES'!$A$2:$A$100,0))),""))
B6: =IF($A6="","",IFERROR(IF(INDEX('WORK PACKAGES'!$B$2:$B$100,MATCH($A6,'WORK PACKAGES'!$A$2:$A$100,0))="","",INDEX('WORK PACKAGES'!$B$2:$B$100,MATCH($A6,'WORK PACKAGES'!$A$2:$A$100,0))),"")) | C6: =IF($A6="","",IFERROR(IF(INDEX('WORK PACKAGES'!$E$2:$E$100,MATCH($A6,'WORK PACKAGES'!$A$2:$A$100,0))="","",INDEX('WORK PACKAGES'!$E$2:$E$100,MATCH($A6,'WORK PACKAGES'!$A$2:$A$100,0))),"")) | E6: =IF($A6="","",IFERROR(IF(INDEX('WP PROGRESS'!$F$2:$F$100,MATCH($A6,'WP PROGRESS'!$A$2:$A$100,0))="","",INDEX('WP PROGRESS'!$F$2:$F$100,MATCH($A6,'WP PROGRESS'!$A$2:$A$100,0))),"")) | F6: =IF($A6="","",IFERROR(IF(INDEX('WP PROGRESS'!$G$2:$G$100,MATCH($A6,'WP PROGRESS'!$A$2:$A$100,0))="","",INDEX('WP PROGRESS'!$G$2:$G$100,MATCH($A6,'WP PROGRESS'!$A$2:$A$100,0))),"")) | G6: =IF($A6="","",IFERROR(IF(INDEX('WP PROGRESS'!$H$2:$H$100,MATCH($A6,'WP PROGRESS'!$A$2:$A$100,0))="","",INDEX('WP PROGRESS'!$H$2:$H$100,MATCH($A6,'WP PROGRESS'!$A$2:$A$100,0))),"")) | H6: =IF($A6="","",IFERROR(IF(INDEX('WP PROGRESS'!$I$2:$I$100,MATCH($A6,'WP PROGRESS'!$A$2:$A$100,0))="","",INDEX('WP PROGRESS'!$I$2:$I$100,MATCH($A6,'WP PROGRESS'!$A$2:$A$100,0))),"")) | I6: =IF($A6="","",IFERROR(IF(INDEX('WP PROGRESS'!$K$2:$K$100,MATCH($A6,'WP PROGRESS'!$A$2:$A$100,0))="","",INDEX('WP PROGRESS'!$K$2:$K$100,MATCH($A6,'WP PROGRESS'!$A$2:$A$100,0))),"")) | P6: =IF($A6="","",IFERROR(IF(INDEX('WP PROGRESS'!$V$2:$V$100,MATCH($A6,'WP PROGRESS'!$A$2:$A$100,0))="","",INDEX('WP PROGRESS'!$V$2:$V$100,MATCH($A6,'WP PROGRESS'!$A$2:$A$100,0))),"")) | Q6: =IF($A6="","",IFERROR(IF(INDEX('WP PROGRESS'!$E$2:$E$100,MATCH($A6,'WP PROGRESS'!$A$2:$A$100,0))="","",INDEX('WP PROGRESS'!$E$2:$E$100,MATCH($A6,'WP PROGRESS'!$A$2:$A$100,0))),"")) | R6: =IF($A6="","",IFERROR(IF(INDEX('WP PROGRESS'!$Z$2:$Z$100,MATCH($A6,'WP PROGRESS'!$A$2:$A$100,0))="","",INDEX('WP PROGRESS'!$Z$2:$Z$100,MATCH($A6,'WP PROGRESS'!$A$2:$A$100,0))),"")) | S6: =IF($A6="","",COUNTIFS(ISSUES!$P$5:$P$200,"*"&$A6&"*",ISSUES!$H$5:$H$200,"<>Closed",ISSUES!$H$5:$H$200,"<>Resolved",ISSUES!$H$5:$H$200,"<>Cancelled",ISSUES!$H$5:$H$200,"<>",ISSUES!$A$5:$A$200,"<>")) | U6: =IF($A6="","",IFERROR(IF(INDEX('WORK PACKAGES'!$G$2:$G$100,MATCH($A6,'WORK PACKAGES'!$A$2:$A$100,0))="","",INDEX('WORK PACKAGES'!$G$2:$G$100,MATCH($A6,'WORK PACKAGES'!$A$2:$A$100,0))),""))
B7: =IF($A7="","",IFERROR(IF(INDEX('WORK PACKAGES'!$B$2:$B$100,MATCH($A7,'WORK PACKAGES'!$A$2:$A$100,0))="","",INDEX('WORK PACKAGES'!$B$2:$B$100,MATCH($A7,'WORK PACKAGES'!$A$2:$A$100,0))),"")) | C7: =IF($A7="","",IFERROR(IF(INDEX('WORK PACKAGES'!$E$2:$E$100,MATCH($A7,'WORK PACKAGES'!$A$2:$A$100,0))="","",INDEX('WORK PACKAGES'!$E$2:$E$100,MATCH($A7,'WORK PACKAGES'!$A$2:$A$100,0))),"")) | E7: =IF($A7="","",IFERROR(IF(INDEX('WP PROGRESS'!$F$2:$F$100,MATCH($A7,'WP PROGRESS'!$A$2:$A$100,0))="","",INDEX('WP PROGRESS'!$F$2:$F$100,MATCH($A7,'WP PROGRESS'!$A$2:$A$100,0))),"")) | F7: =IF($A7="","",IFERROR(IF(INDEX('WP PROGRESS'!$G$2:$G$100,MATCH($A7,'WP PROGRESS'!$A$2:$A$100,0))="","",INDEX('WP PROGRESS'!$G$2:$G$100,MATCH($A7,'WP PROGRESS'!$A$2:$A$100,0))),"")) | G7: =IF($A7="","",IFERROR(IF(INDEX('WP PROGRESS'!$H$2:$H$100,MATCH($A7,'WP PROGRESS'!$A$2:$A$100,0))="","",INDEX('WP PROGRESS'!$H$2:$H$100,MATCH($A7,'WP PROGRESS'!$A$2:$A$100,0))),"")) | H7: =IF($A7="","",IFERROR(IF(INDEX('WP PROGRESS'!$I$2:$I$100,MATCH($A7,'WP PROGRESS'!$A$2:$A$100,0))="","",INDEX('WP PROGRESS'!$I$2:$I$100,MATCH($A7,'WP PROGRESS'!$A$2:$A$100,0))),"")) | I7: =IF($A7="","",IFERROR(IF(INDEX('WP PROGRESS'!$K$2:$K$100,MATCH($A7,'WP PROGRESS'!$A$2:$A$100,0))="","",INDEX('WP PROGRESS'!$K$2:$K$100,MATCH($A7,'WP PROGRESS'!$A$2:$A$100,0))),"")) | P7: =IF($A7="","",IFERROR(IF(INDEX('WP PROGRESS'!$V$2:$V$100,MATCH($A7,'WP PROGRESS'!$A$2:$A$100,0))="","",INDEX('WP PROGRESS'!$V$2:$V$100,MATCH($A7,'WP PROGRESS'!$A$2:$A$100,0))),"")) | Q7: =IF($A7="","",IFERROR(IF(INDEX('WP PROGRESS'!$E$2:$E$100,MATCH($A7,'WP PROGRESS'!$A$2:$A$100,0))="","",INDEX('WP PROGRESS'!$E$2:$E$100,MATCH($A7,'WP PROGRESS'!$A$2:$A$100,0))),"")) | R7: =IF($A7="","",IFERROR(IF(INDEX('WP PROGRESS'!$Z$2:$Z$100,MATCH($A7,'WP PROGRESS'!$A$2:$A$100,0))="","",INDEX('WP PROGRESS'!$Z$2:$Z$100,MATCH($A7,'WP PROGRESS'!$A$2:$A$100,0))),"")) | S7: =IF($A7="","",COUNTIFS(ISSUES!$P$5:$P$200,"*"&$A7&"*",ISSUES!$H$5:$H$200,"<>Closed",ISSUES!$H$5:$H$200,"<>Resolved",ISSUES!$H$5:$H$200,"<>Cancelled",ISSUES!$H$5:$H$200,"<>",ISSUES!$A$5:$A$200,"<>")) | U7: =IF($A7="","",IFERROR(IF(INDEX('WORK PACKAGES'!$G$2:$G$100,MATCH($A7,'WORK PACKAGES'!$A$2:$A$100,0))="","",INDEX('WORK PACKAGES'!$G$2:$G$100,MATCH($A7,'WORK PACKAGES'!$A$2:$A$100,0))),""))
B8: =IF($A8="","",IFERROR(IF(INDEX('WORK PACKAGES'!$B$2:$B$100,MATCH($A8,'WORK PACKAGES'!$A$2:$A$100,0))="","",INDEX('WORK PACKAGES'!$B$2:$B$100,MATCH($A8,'WORK PACKAGES'!$A$2:$A$100,0))),"")) | C8: =IF($A8="","",IFERROR(IF(INDEX('WORK PACKAGES'!$E$2:$E$100,MATCH($A8,'WORK PACKAGES'!$A$2:$A$100,0))="","",INDEX('WORK PACKAGES'!$E$2:$E$100,MATCH($A8,'WORK PACKAGES'!$A$2:$A$100,0))),"")) | E8: =IF($A8="","",IFERROR(IF(INDEX('WP PROGRESS'!$F$2:$F$100,MATCH($A8,'WP PROGRESS'!$A$2:$A$100,0))="","",INDEX('WP PROGRESS'!$F$2:$F$100,MATCH($A8,'WP PROGRESS'!$A$2:$A$100,0))),"")) | F8: =IF($A8="","",IFERROR(IF(INDEX('WP PROGRESS'!$G$2:$G$100,MATCH($A8,'WP PROGRESS'!$A$2:$A$100,0))="","",INDEX('WP PROGRESS'!$G$2:$G$100,MATCH($A8,'WP PROGRESS'!$A$2:$A$100,0))),"")) | G8: =IF($A8="","",IFERROR(IF(INDEX('WP PROGRESS'!$H$2:$H$100,MATCH($A8,'WP PROGRESS'!$A$2:$A$100,0))="","",INDEX('WP PROGRESS'!$H$2:$H$100,MATCH($A8,'WP PROGRESS'!$A$2:$A$100,0))),"")) | H8: =IF($A8="","",IFERROR(IF(INDEX('WP PROGRESS'!$I$2:$I$100,MATCH($A8,'WP PROGRESS'!$A$2:$A$100,0))="","",INDEX('WP PROGRESS'!$I$2:$I$100,MATCH($A8,'WP PROGRESS'!$A$2:$A$100,0))),"")) | I8: =IF($A8="","",IFERROR(IF(INDEX('WP PROGRESS'!$K$2:$K$100,MATCH($A8,'WP PROGRESS'!$A$2:$A$100,0))="","",INDEX('WP PROGRESS'!$K$2:$K$100,MATCH($A8,'WP PROGRESS'!$A$2:$A$100,0))),"")) | P8: =IF($A8="","",IFERROR(IF(INDEX('WP PROGRESS'!$V$2:$V$100,MATCH($A8,'WP PROGRESS'!$A$2:$A$100,0))="","",INDEX('WP PROGRESS'!$V$2:$V$100,MATCH($A8,'WP PROGRESS'!$A$2:$A$100,0))),"")) | Q8: =IF($A8="","",IFERROR(IF(INDEX('WP PROGRESS'!$E$2:$E$100,MATCH($A8,'WP PROGRESS'!$A$2:$A$100,0))="","",INDEX('WP PROGRESS'!$E$2:$E$100,MATCH($A8,'WP PROGRESS'!$A$2:$A$100,0))),"")) | R8: =IF($A8="","",IFERROR(IF(INDEX('WP PROGRESS'!$Z$2:$Z$100,MATCH($A8,'WP PROGRESS'!$A$2:$A$100,0))="","",INDEX('WP PROGRESS'!$Z$2:$Z$100,MATCH($A8,'WP PROGRESS'!$A$2:$A$100,0))),"")) | S8: =IF($A8="","",COUNTIFS(ISSUES!$P$5:$P$200,"*"&$A8&"*",ISSUES!$H$5:$H$200,"<>Closed",ISSUES!$H$5:$H$200,"<>Resolved",ISSUES!$H$5:$H$200,"<>Cancelled",ISSUES!$H$5:$H$200,"<>",ISSUES!$A$5:$A$200,"<>")) | U8: =IF($A8="","",IFERROR(IF(INDEX('WORK PACKAGES'!$G$2:$G$100,MATCH($A8,'WORK PACKAGES'!$A$2:$A$100,0))="","",INDEX('WORK PACKAGES'!$G$2:$G$100,MATCH($A8,'WORK PACKAGES'!$A$2:$A$100,0))),""))
B9: =IF($A9="","",IFERROR(IF(INDEX('WORK PACKAGES'!$B$2:$B$100,MATCH($A9,'WORK PACKAGES'!$A$2:$A$100,0))="","",INDEX('WORK PACKAGES'!$B$2:$B$100,MATCH($A9,'WORK PACKAGES'!$A$2:$A$100,0))),"")) | C9: =IF($A9="","",IFERROR(IF(INDEX('WORK PACKAGES'!$E$2:$E$100,MATCH($A9,'WORK PACKAGES'!$A$2:$A$100,0))="","",INDEX('WORK PACKAGES'!$E$2:$E$100,MATCH($A9,'WORK PACKAGES'!$A$2:$A$100,0))),"")) | E9: =IF($A9="","",IFERROR(IF(INDEX('WP PROGRESS'!$F$2:$F$100,MATCH($A9,'WP PROGRESS'!$A$2:$A$100,0))="","",INDEX('WP PROGRESS'!$F$2:$F$100,MATCH($A9,'WP PROGRESS'!$A$2:$A$100,0))),"")) | F9: =IF($A9="","",IFERROR(IF(INDEX('WP PROGRESS'!$G$2:$G$100,MATCH($A9,'WP PROGRESS'!$A$2:$A$100,0))="","",INDEX('WP PROGRESS'!$G$2:$G$100,MATCH($A9,'WP PROGRESS'!$A$2:$A$100,0))),"")) | G9: =IF($A9="","",IFERROR(IF(INDEX('WP PROGRESS'!$H$2:$H$100,MATCH($A9,'WP PROGRESS'!$A$2:$A$100,0))="","",INDEX('WP PROGRESS'!$H$2:$H$100,MATCH($A9,'WP PROGRESS'!$A$2:$A$100,0))),"")) | H9: =IF($A9="","",IFERROR(IF(INDEX('WP PROGRESS'!$I$2:$I$100,MATCH($A9,'WP PROGRESS'!$A$2:$A$100,0))="","",INDEX('WP PROGRESS'!$I$2:$I$100,MATCH($A9,'WP PROGRESS'!$A$2:$A$100,0))),"")) | I9: =IF($A9="","",IFERROR(IF(INDEX('WP PROGRESS'!$K$2:$K$100,MATCH($A9,'WP PROGRESS'!$A$2:$A$100,0))="","",INDEX('WP PROGRESS'!$K$2:$K$100,MATCH($A9,'WP PROGRESS'!$A$2:$A$100,0))),"")) | P9: =IF($A9="","",IFERROR(IF(INDEX('WP PROGRESS'!$V$2:$V$100,MATCH($A9,'WP PROGRESS'!$A$2:$A$100,0))="","",INDEX('WP PROGRESS'!$V$2:$V$100,MATCH($A9,'WP PROGRESS'!$A$2:$A$100,0))),"")) | Q9: =IF($A9="","",IFERROR(IF(INDEX('WP PROGRESS'!$E$2:$E$100,MATCH($A9,'WP PROGRESS'!$A$2:$A$100,0))="","",INDEX('WP PROGRESS'!$E$2:$E$100,MATCH($A9,'WP PROGRESS'!$A$2:$A$100,0))),"")) | R9: =IF($A9="","",IFERROR(IF(INDEX('WP PROGRESS'!$Z$2:$Z$100,MATCH($A9,'WP PROGRESS'!$A$2:$A$100,0))="","",INDEX('WP PROGRESS'!$Z$2:$Z$100,MATCH($A9,'WP PROGRESS'!$A$2:$A$100,0))),"")) | S9: =IF($A9="","",COUNTIFS(ISSUES!$P$5:$P$200,"*"&$A9&"*",ISSUES!$H$5:$H$200,"<>Closed",ISSUES!$H$5:$H$200,"<>Resolved",ISSUES!$H$5:$H$200,"<>Cancelled",ISSUES!$H$5:$H$200,"<>",ISSUES!$A$5:$A$200,"<>")) | U9: =IF($A9="","",IFERROR(IF(INDEX('WORK PACKAGES'!$G$2:$G$100,MATCH($A9,'WORK PACKAGES'!$A$2:$A$100,0))="","",INDEX('WORK PACKAGES'!$G$2:$G$100,MATCH($A9,'WORK PACKAGES'!$A$2:$A$100,0))),""))
B10: =IF($A10="","",IFERROR(IF(INDEX('WORK PACKAGES'!$B$2:$B$100,MATCH($A10,'WORK PACKAGES'!$A$2:$A$100,0))="","",INDEX('WORK PACKAGES'!$B$2:$B$100,MATCH($A10,'WORK PACKAGES'!$A$2:$A$100,0))),"")) | C10: =IF($A10="","",IFERROR(IF(INDEX('WORK PACKAGES'!$E$2:$E$100,MATCH($A10,'WORK PACKAGES'!$A$2:$A$100,0))="","",INDEX('WORK PACKAGES'!$E$2:$E$100,MATCH($A10,'WORK PACKAGES'!$A$2:$A$100,0))),"")) | E10: =IF($A10="","",IFERROR(IF(INDEX('WP PROGRESS'!$F$2:$F$100,MATCH($A10,'WP PROGRESS'!$A$2:$A$100,0))="","",INDEX('WP PROGRESS'!$F$2:$F$100,MATCH($A10,'WP PROGRESS'!$A$2:$A$100,0))),"")) | F10: =IF($A10="","",IFERROR(IF(INDEX('WP PROGRESS'!$G$2:$G$100,MATCH($A10,'WP PROGRESS'!$A$2:$A$100,0))="","",INDEX('WP PROGRESS'!$G$2:$G$100,MATCH($A10,'WP PROGRESS'!$A$2:$A$100,0))),"")) | G10: =IF($A10="","",IFERROR(IF(INDEX('WP PROGRESS'!$H$2:$H$100,MATCH($A10,'WP PROGRESS'!$A$2:$A$100,0))="","",INDEX('WP PROGRESS'!$H$2:$H$100,MATCH($A10,'WP PROGRESS'!$A$2:$A$100,0))),"")) | H10: =IF($A10="","",IFERROR(IF(INDEX('WP PROGRESS'!$I$2:$I$100,MATCH($A10,'WP PROGRESS'!$A$2:$A$100,0))="","",INDEX('WP PROGRESS'!$I$2:$I$100,MATCH($A10,'WP PROGRESS'!$A$2:$A$100,0))),"")) | I10: =IF($A10="","",IFERROR(IF(INDEX('WP PROGRESS'!$K$2:$K$100,MATCH($A10,'WP PROGRESS'!$A$2:$A$100,0))="","",INDEX('WP PROGRESS'!$K$2:$K$100,MATCH($A10,'WP PROGRESS'!$A$2:$A$100,0))),"")) | P10: =IF($A10="","",IFERROR(IF(INDEX('WP PROGRESS'!$V$2:$V$100,MATCH($A10,'WP PROGRESS'!$A$2:$A$100,0))="","",INDEX('WP PROGRESS'!$V$2:$V$100,MATCH($A10,'WP PROGRESS'!$A$2:$A$100,0))),"")) | Q10: =IF($A10="","",IFERROR(IF(INDEX('WP PROGRESS'!$E$2:$E$100,MATCH($A10,'WP PROGRESS'!$A$2:$A$100,0))="","",INDEX('WP PROGRESS'!$E$2:$E$100,MATCH($A10,'WP PROGRESS'!$A$2:$A$100,0))),"")) | R10: =IF($A10="","",IFERROR(IF(INDEX('WP PROGRESS'!$Z$2:$Z$100,MATCH($A10,'WP PROGRESS'!$A$2:$A$100,0))="","",INDEX('WP PROGRESS'!$Z$2:$Z$100,MATCH($A10,'WP PROGRESS'!$A$2:$A$100,0))),"")) | S10: =IF($A10="","",COUNTIFS(ISSUES!$P$5:$P$200,"*"&$A10&"*",ISSUES!$H$5:$H$200,"<>Closed",ISSUES!$H$5:$H$200,"<>Resolved",ISSUES!$H$5:$H$200,"<>Cancelled",ISSUES!$H$5:$H$200,"<>",ISSUES!$A$5:$A$200,"<>")) | U10: =IF($A10="","",IFERROR(IF(INDEX('WORK PACKAGES'!$G$2:$G$100,MATCH($A10,'WORK PACKAGES'!$A$2:$A$100,0))="","",INDEX('WORK PACKAGES'!$G$2:$G$100,MATCH($A10,'WORK PACKAGES'!$A$2:$A$100,0))),""))
B11: =IF($A11="","",IFERROR(IF(INDEX('WORK PACKAGES'!$B$2:$B$100,MATCH($A11,'WORK PACKAGES'!$A$2:$A$100,0))="","",INDEX('WORK PACKAGES'!$B$2:$B$100,MATCH($A11,'WORK PACKAGES'!$A$2:$A$100,0))),"")) | C11: =IF($A11="","",IFERROR(IF(INDEX('WORK PACKAGES'!$E$2:$E$100,MATCH($A11,'WORK PACKAGES'!$A$2:$A$100,0))="","",INDEX('WORK PACKAGES'!$E$2:$E$100,MATCH($A11,'WORK PACKAGES'!$A$2:$A$100,0))),"")) | E11: =IF($A11="","",IFERROR(IF(INDEX('WP PROGRESS'!$F$2:$F$100,MATCH($A11,'WP PROGRESS'!$A$2:$A$100,0))="","",INDEX('WP PROGRESS'!$F$2:$F$100,MATCH($A11,'WP PROGRESS'!$A$2:$A$100,0))),"")) | F11: =IF($A11="","",IFERROR(IF(INDEX('WP PROGRESS'!$G$2:$G$100,MATCH($A11,'WP PROGRESS'!$A$2:$A$100,0))="","",INDEX('WP PROGRESS'!$G$2:$G$100,MATCH($A11,'WP PROGRESS'!$A$2:$A$100,0))),"")) | G11: =IF($A11="","",IFERROR(IF(INDEX('WP PROGRESS'!$H$2:$H$100,MATCH($A11,'WP PROGRESS'!$A$2:$A$100,0))="","",INDEX('WP PROGRESS'!$H$2:$H$100,MATCH($A11,'WP PROGRESS'!$A$2:$A$100,0))),"")) | H11: =IF($A11="","",IFERROR(IF(INDEX('WP PROGRESS'!$I$2:$I$100,MATCH($A11,'WP PROGRESS'!$A$2:$A$100,0))="","",INDEX('WP PROGRESS'!$I$2:$I$100,MATCH($A11,'WP PROGRESS'!$A$2:$A$100,0))),"")) | I11: =IF($A11="","",IFERROR(IF(INDEX('WP PROGRESS'!$K$2:$K$100,MATCH($A11,'WP PROGRESS'!$A$2:$A$100,0))="","",INDEX('WP PROGRESS'!$K$2:$K$100,MATCH($A11,'WP PROGRESS'!$A$2:$A$100,0))),"")) | P11: =IF($A11="","",IFERROR(IF(INDEX('WP PROGRESS'!$V$2:$V$100,MATCH($A11,'WP PROGRESS'!$A$2:$A$100,0))="","",INDEX('WP PROGRESS'!$V$2:$V$100,MATCH($A11,'WP PROGRESS'!$A$2:$A$100,0))),"")) | Q11: =IF($A11="","",IFERROR(IF(INDEX('WP PROGRESS'!$E$2:$E$100,MATCH($A11,'WP PROGRESS'!$A$2:$A$100,0))="","",INDEX('WP PROGRESS'!$E$2:$E$100,MATCH($A11,'WP PROGRESS'!$A$2:$A$100,0))),"")) | R11: =IF($A11="","",IFERROR(IF(INDEX('WP PROGRESS'!$Z$2:$Z$100,MATCH($A11,'WP PROGRESS'!$A$2:$A$100,0))="","",INDEX('WP PROGRESS'!$Z$2:$Z$100,MATCH($A11,'WP PROGRESS'!$A$2:$A$100,0))),"")) | S11: =IF($A11="","",COUNTIFS(ISSUES!$P$5:$P$200,"*"&$A11&"*",ISSUES!$H$5:$H$200,"<>Closed",ISSUES!$H$5:$H$200,"<>Resolved",ISSUES!$H$5:$H$200,"<>Cancelled",ISSUES!$H$5:$H$200,"<>",ISSUES!$A$5:$A$200,"<>")) | U11: =IF($A11="","",IFERROR(IF(INDEX('WORK PACKAGES'!$G$2:$G$100,MATCH($A11,'WORK PACKAGES'!$A$2:$A$100,0))="","",INDEX('WORK PACKAGES'!$G$2:$G$100,MATCH($A11,'WORK PACKAGES'!$A$2:$A$100,0))),""))
B12: =IF($A12="","",IFERROR(IF(INDEX('WORK PACKAGES'!$B$2:$B$100,MATCH($A12,'WORK PACKAGES'!$A$2:$A$100,0))="","",INDEX('WORK PACKAGES'!$B$2:$B$100,MATCH($A12,'WORK PACKAGES'!$A$2:$A$100,0))),"")) | C12: =IF($A12="","",IFERROR(IF(INDEX('WORK PACKAGES'!$E$2:$E$100,MATCH($A12,'WORK PACKAGES'!$A$2:$A$100,0))="","",INDEX('WORK PACKAGES'!$E$2:$E$100,MATCH($A12,'WORK PACKAGES'!$A$2:$A$100,0))),"")) | E12: =IF($A12="","",IFERROR(IF(INDEX('WP PROGRESS'!$F$2:$F$100,MATCH($A12,'WP PROGRESS'!$A$2:$A$100,0))="","",INDEX('WP PROGRESS'!$F$2:$F$100,MATCH($A12,'WP PROGRESS'!$A$2:$A$100,0))),"")) | F12: =IF($A12="","",IFERROR(IF(INDEX('WP PROGRESS'!$G$2:$G$100,MATCH($A12,'WP PROGRESS'!$A$2:$A$100,0))="","",INDEX('WP PROGRESS'!$G$2:$G$100,MATCH($A12,'WP PROGRESS'!$A$2:$A$100,0))),"")) | G12: =IF($A12="","",IFERROR(IF(INDEX('WP PROGRESS'!$H$2:$H$100,MATCH($A12,'WP PROGRESS'!$A$2:$A$100,0))="","",INDEX('WP PROGRESS'!$H$2:$H$100,MATCH($A12,'WP PROGRESS'!$A$2:$A$100,0))),"")) | H12: =IF($A12="","",IFERROR(IF(INDEX('WP PROGRESS'!$I$2:$I$100,MATCH($A12,'WP PROGRESS'!$A$2:$A$100,0))="","",INDEX('WP PROGRESS'!$I$2:$I$100,MATCH($A12,'WP PROGRESS'!$A$2:$A$100,0))),"")) | I12: =IF($A12="","",IFERROR(IF(INDEX('WP PROGRESS'!$K$2:$K$100,MATCH($A12,'WP PROGRESS'!$A$2:$A$100,0))="","",INDEX('WP PROGRESS'!$K$2:$K$100,MATCH($A12,'WP PROGRESS'!$A$2:$A$100,0))),"")) | P12: =IF($A12="","",IFERROR(IF(INDEX('WP PROGRESS'!$V$2:$V$100,MATCH($A12,'WP PROGRESS'!$A$2:$A$100,0))="","",INDEX('WP PROGRESS'!$V$2:$V$100,MATCH($A12,'WP PROGRESS'!$A$2:$A$100,0))),"")) | Q12: =IF($A12="","",IFERROR(IF(INDEX('WP PROGRESS'!$E$2:$E$100,MATCH($A12,'WP PROGRESS'!$A$2:$A$100,0))="","",INDEX('WP PROGRESS'!$E$2:$E$100,MATCH($A12,'WP PROGRESS'!$A$2:$A$100,0))),"")) | R12: =IF($A12="","",IFERROR(IF(INDEX('WP PROGRESS'!$Z$2:$Z$100,MATCH($A12,'WP PROGRESS'!$A$2:$A$100,0))="","",INDEX('WP PROGRESS'!$Z$2:$Z$100,MATCH($A12,'WP PROGRESS'!$A$2:$A$100,0))),"")) | S12: =IF($A12="","",COUNTIFS(ISSUES!$P$5:$P$200,"*"&$A12&"*",ISSUES!$H$5:$H$200,"<>Closed",ISSUES!$H$5:$H$200,"<>Resolved",ISSUES!$H$5:$H$200,"<>Cancelled",ISSUES!$H$5:$H$200,"<>",ISSUES!$A$5:$A$200,"<>")) | U12: =IF($A12="","",IFERROR(IF(INDEX('WORK PACKAGES'!$G$2:$G$100,MATCH($A12,'WORK PACKAGES'!$A$2:$A$100,0))="","",INDEX('WORK PACKAGES'!$G$2:$G$100,MATCH($A12,'WORK PACKAGES'!$A$2:$A$100,0))),""))
B13: =IF($A13="","",IFERROR(IF(INDEX('WORK PACKAGES'!$B$2:$B$100,MATCH($A13,'WORK PACKAGES'!$A$2:$A$100,0))="","",INDEX('WORK PACKAGES'!$B$2:$B$100,MATCH($A13,'WORK PACKAGES'!$A$2:$A$100,0))),"")) | C13: =IF($A13="","",IFERROR(IF(INDEX('WORK PACKAGES'!$E$2:$E$100,MATCH($A13,'WORK PACKAGES'!$A$2:$A$100,0))="","",INDEX('WORK PACKAGES'!$E$2:$E$100,MATCH($A13,'WORK PACKAGES'!$A$2:$A$100,0))),"")) | E13: =IF($A13="","",IFERROR(IF(INDEX('WP PROGRESS'!$F$2:$F$100,MATCH($A13,'WP PROGRESS'!$A$2:$A$100,0))="","",INDEX('WP PROGRESS'!$F$2:$F$100,MATCH($A13,'WP PROGRESS'!$A$2:$A$100,0))),"")) | F13: =IF($A13="","",IFERROR(IF(INDEX('WP PROGRESS'!$G$2:$G$100,MATCH($A13,'WP PROGRESS'!$A$2:$A$100,0))="","",INDEX('WP PROGRESS'!$G$2:$G$100,MATCH($A13,'WP PROGRESS'!$A$2:$A$100,0))),"")) | G13: =IF($A13="","",IFERROR(IF(INDEX('WP PROGRESS'!$H$2:$H$100,MATCH($A13,'WP PROGRESS'!$A$2:$A$100,0))="","",INDEX('WP PROGRESS'!$H$2:$H$100,MATCH($A13,'WP PROGRESS'!$A$2:$A$100,0))),"")) | H13: =IF($A13="","",IFERROR(IF(INDEX('WP PROGRESS'!$I$2:$I$100,MATCH($A13,'WP PROGRESS'!$A$2:$A$100,0))="","",INDEX('WP PROGRESS'!$I$2:$I$100,MATCH($A13,'WP PROGRESS'!$A$2:$A$100,0))),"")) | I13: =IF($A13="","",IFERROR(IF(INDEX('WP PROGRESS'!$K$2:$K$100,MATCH($A13,'WP PROGRESS'!$A$2:$A$100,0))="","",INDEX('WP PROGRESS'!$K$2:$K$100,MATCH($A13,'WP PROGRESS'!$A$2:$A$100,0))),"")) | P13: =IF($A13="","",IFERROR(IF(INDEX('WP PROGRESS'!$V$2:$V$100,MATCH($A13,'WP PROGRESS'!$A$2:$A$100,0))="","",INDEX('WP PROGRESS'!$V$2:$V$100,MATCH($A13,'WP PROGRESS'!$A$2:$A$100,0))),"")) | Q13: =IF($A13="","",IFERROR(IF(INDEX('WP PROGRESS'!$E$2:$E$100,MATCH($A13,'WP PROGRESS'!$A$2:$A$100,0))="","",INDEX('WP PROGRESS'!$E$2:$E$100,MATCH($A13,'WP PROGRESS'!$A$2:$A$100,0))),"")) | R13: =IF($A13="","",IFERROR(IF(INDEX('WP PROGRESS'!$Z$2:$Z$100,MATCH($A13,'WP PROGRESS'!$A$2:$A$100,0))="","",INDEX('WP PROGRESS'!$Z$2:$Z$100,MATCH($A13,'WP PROGRESS'!$A$2:$A$100,0))),"")) | S13: =IF($A13="","",COUNTIFS(ISSUES!$P$5:$P$200,"*"&$A13&"*",ISSUES!$H$5:$H$200,"<>Closed",ISSUES!$H$5:$H$200,"<>Resolved",ISSUES!$H$5:$H$200,"<>Cancelled",ISSUES!$H$5:$H$200,"<>",ISSUES!$A$5:$A$200,"<>")) | U13: =IF($A13="","",IFERROR(IF(INDEX('WORK PACKAGES'!$G$2:$G$100,MATCH($A13,'WORK PACKAGES'!$A$2:$A$100,0))="","",INDEX('WORK PACKAGES'!$G$2:$G$100,MATCH($A13,'WORK PACKAGES'!$A$2:$A$100,0))),""))
B14: =IF($A14="","",IFERROR(IF(INDEX('WORK PACKAGES'!$B$2:$B$100,MATCH($A14,'WORK PACKAGES'!$A$2:$A$100,0))="","",INDEX('WORK PACKAGES'!$B$2:$B$100,MATCH($A14,'WORK PACKAGES'!$A$2:$A$100,0))),"")) | C14: =IF($A14="","",IFERROR(IF(INDEX('WORK PACKAGES'!$E$2:$E$100,MATCH($A14,'WORK PACKAGES'!$A$2:$A$100,0))="","",INDEX('WORK PACKAGES'!$E$2:$E$100,MATCH($A14,'WORK PACKAGES'!$A$2:$A$100,0))),"")) | E14: =IF($A14="","",IFERROR(IF(INDEX('WP PROGRESS'!$F$2:$F$100,MATCH($A14,'WP PROGRESS'!$A$2:$A$100,0))="","",INDEX('WP PROGRESS'!$F$2:$F$100,MATCH($A14,'WP PROGRESS'!$A$2:$A$100,0))),"")) | F14: =IF($A14="","",IFERROR(IF(INDEX('WP PROGRESS'!$G$2:$G$100,MATCH($A14,'WP PROGRESS'!$A$2:$A$100,0))="","",INDEX('WP PROGRESS'!$G$2:$G$100,MATCH($A14,'WP PROGRESS'!$A$2:$A$100,0))),"")) | G14: =IF($A14="","",IFERROR(IF(INDEX('WP PROGRESS'!$H$2:$H$100,MATCH($A14,'WP PROGRESS'!$A$2:$A$100,0))="","",INDEX('WP PROGRESS'!$H$2:$H$100,MATCH($A14,'WP PROGRESS'!$A$2:$A$100,0))),"")) | H14: =IF($A14="","",IFERROR(IF(INDEX('WP PROGRESS'!$I$2:$I$100,MATCH($A14,'WP PROGRESS'!$A$2:$A$100,0))="","",INDEX('WP PROGRESS'!$I$2:$I$100,MATCH($A14,'WP PROGRESS'!$A$2:$A$100,0))),"")) | I14: =IF($A14="","",IFERROR(IF(INDEX('WP PROGRESS'!$K$2:$K$100,MATCH($A14,'WP PROGRESS'!$A$2:$A$100,0))="","",INDEX('WP PROGRESS'!$K$2:$K$100,MATCH($A14,'WP PROGRESS'!$A$2:$A$100,0))),"")) | P14: =IF($A14="","",IFERROR(IF(INDEX('WP PROGRESS'!$V$2:$V$100,MATCH($A14,'WP PROGRESS'!$A$2:$A$100,0))="","",INDEX('WP PROGRESS'!$V$2:$V$100,MATCH($A14,'WP PROGRESS'!$A$2:$A$100,0))),"")) | Q14: =IF($A14="","",IFERROR(IF(INDEX('WP PROGRESS'!$E$2:$E$100,MATCH($A14,'WP PROGRESS'!$A$2:$A$100,0))="","",INDEX('WP PROGRESS'!$E$2:$E$100,MATCH($A14,'WP PROGRESS'!$A$2:$A$100,0))),"")) | R14: =IF($A14="","",IFERROR(IF(INDEX('WP PROGRESS'!$Z$2:$Z$100,MATCH($A14,'WP PROGRESS'!$A$2:$A$100,0))="","",INDEX('WP PROGRESS'!$Z$2:$Z$100,MATCH($A14,'WP PROGRESS'!$A$2:$A$100,0))),"")) | S14: =IF($A14="","",COUNTIFS(ISSUES!$P$5:$P$200,"*"&$A14&"*",ISSUES!$H$5:$H$200,"<>Closed",ISSUES!$H$5:$H$200,"<>Resolved",ISSUES!$H$5:$H$200,"<>Cancelled",ISSUES!$H$5:$H$200,"<>",ISSUES!$A$5:$A$200,"<>")) | U14: =IF($A14="","",IFERROR(IF(INDEX('WORK PACKAGES'!$G$2:$G$100,MATCH($A14,'WORK PACKAGES'!$A$2:$A$100,0))="","",INDEX('WORK PACKAGES'!$G$2:$G$100,MATCH($A14,'WORK PACKAGES'!$A$2:$A$100,0))),""))
... B51: =IF($A51="","",IFERROR(IF(INDEX('WORK PACKAGES'!$B$2:$B$100,MATCH($A51,'WORK PACKAGES'!$A$2:$A$100,0))="","",INDEX('WORK PACKAGES'!$B$2:$B$100,MATCH($A51,'WORK PACKAGES'!$A$2:$A$100,0))),"")) | C51: =IF($A51="","",IFERROR(IF(INDEX('WORK PACKAGES'!$E$2:$E$100,MATCH($A51,'WORK PACKAGES'!$A$2:$A$100,0))="","",INDEX('WORK PACKAGES'!$E$2:$E$100,MATCH($A51,'WORK PACKAGES'!$A$2:$A$100,0))),"")) | E51: =IF($A51="","",IFERROR(IF(INDEX('WP PROGRESS'!$F$2:$F$100,MATCH($A51,'WP PROGRESS'!$A$2:$A$100,0))="","",INDEX('WP PROGRESS'!$F$2:$F$100,MATCH($A51,'WP PROGRESS'!$A$2:$A$100,0))),"")) | F51: =IF($A51="","",IFERROR(IF(INDEX('WP PROGRESS'!$G$2:$G$100,MATCH($A51,'WP PROGRESS'!$A$2:$A$100,0))="","",INDEX('WP PROGRESS'!$G$2:$G$100,MATCH($A51,'WP PROGRESS'!$A$2:$A$100,0))),"")) | G51: =IF($A51="","",IFERROR(IF(INDEX('WP PROGRESS'!$H$2:$H$100,MATCH($A51,'WP PROGRESS'!$A$2:$A$100,0))="","",INDEX('WP PROGRESS'!$H$2:$H$100,MATCH($A51,'WP PROGRESS'!$A$2:$A$100,0))),"")) | H51: =IF($A51="","",IFERROR(IF(INDEX('WP PROGRESS'!$I$2:$I$100,MATCH($A51,'WP PROGRESS'!$A$2:$A$100,0))="","",INDEX('WP PROGRESS'!$I$2:$I$100,MATCH($A51,'WP PROGRESS'!$A$2:$A$100,0))),"")) | I51: =IF($A51="","",IFERROR(IF(INDEX('WP PROGRESS'!$K$2:$K$100,MATCH($A51,'WP PROGRESS'!$A$2:$A$100,0))="","",INDEX('WP PROGRESS'!$K$2:$K$100,MATCH($A51,'WP PROGRESS'!$A$2:$A$100,0))),"")) | P51: =IF($A51="","",IFERROR(IF(INDEX('WP PROGRESS'!$V$2:$V$100,MATCH($A51,'WP PROGRESS'!$A$2:$A$100,0))="","",INDEX('WP PROGRESS'!$V$2:$V$100,MATCH($A51,'WP PROGRESS'!$A$2:$A$100,0))),"")) | Q51: =IF($A51="","",IFERROR(IF(INDEX('WP PROGRESS'!$E$2:$E$100,MATCH($A51,'WP PROGRESS'!$A$2:$A$100,0))="","",INDEX('WP PROGRESS'!$E$2:$E$100,MATCH($A51,'WP PROGRESS'!$A$2:$A$100,0))),"")) | R51: =IF($A51="","",IFERROR(IF(INDEX('WP PROGRESS'!$Z$2:$Z$100,MATCH($A51,'WP PROGRESS'!$A$2:$A$100,0))="","",INDEX('WP PROGRESS'!$Z$2:$Z$100,MATCH($A51,'WP PROGRESS'!$A$2:$A$100,0))),"")) | S51: =IF($A51="","",COUNTIFS(ISSUES!$P$5:$P$200,"*"&$A51&"*",ISSUES!$H$5:$H$200,"<>Closed",ISSUES!$H$5:$H$200,"<>Resolved",ISSUES!$H$5:$H$200,"<>Cancelled",ISSUES!$H$5:$H$200,"<>",ISSUES!$A$5:$A$200,"<>")) | U51: =IF($A51="","",IFERROR(IF(INDEX('WORK PACKAGES'!$G$2:$G$100,MATCH($A51,'WORK PACKAGES'!$A$2:$A$100,0))="","",INDEX('WORK PACKAGES'!$G$2:$G$100,MATCH($A51,'WORK PACKAGES'!$A$2:$A$100,0))),""))

Sheet SCOPE DASHBOARD
A1: SCOPE DASHBOARD | ENGINEERING REVIEW
A2: Scope rows are manually identified by Scope ID. Values below are calculated; blocking X is human-managed. No automatic flag propagation.
A3: Scope progress (H:M) is derived from WP PROGRESS: average of each column over work packages whose Primary Scope is this scope, each WP weighted equally. Blank and '--' are left out; enter 0 for 'in use, not started'. Blocked? (X) stays human-managed; 'Blocked WPs' is information only.
A4: Scope ID | B4: Engineering Scope | C4: WP Count | D4: Open Issues | E4: Open RFIs | F4: Blocked? (X) | G4: Engineering State | H4: Eng % | I4: Prog % | J4: Cond & Wire % | K4: Device % | L4: Loop Check % | M4: PreComm % | N4: WPs Gate Complete | O4: Blocked WPs (count)
B5: =IF($A5="","",IFERROR(INDEX(SCOPES!$B$5:$B$200,MATCH($A5,SCOPES!$A$5:$A$200,0)),"")) | C5: =IF($A5="","",COUNTIF('WORK PACKAGES'!$G$2:$G$100,$A5)) | D5: =IF($A5="","",COUNTIFS(ISSUES!$O$5:$O$200,$A5,ISSUES!$H$5:$H$200,"<>Closed",ISSUES!$H$5:$H$200,"<>Resolved",ISSUES!$H$5:$H$200,"<>Cancelled",ISSUES!$H$5:$H$200,"<>",ISSUES!$A$5:$A$200,"<>")) | E5: =IF($A5="","",COUNTIFS('RFI REGISTER'!$F$5:$F$250,"*"&$A5&"*",'RFI REGISTER'!$C$5:$C$250,"<>Closed",'RFI REGISTER'!$C$5:$C$250,"<>Cancelled",'RFI REGISTER'!$C$5:$C$250,"<>",'RFI REGISTER'!$A$5:$A$250,"<>")) | G5: =IF($A5="","",IFERROR(INDEX(SCOPES!$K$5:$K$200,MATCH($A5,SCOPES!$A$5:$A$200,0)),"")) | H5: =IF($A5="","",IFERROR(AVERAGEIFS('WP PROGRESS'!$F$2:$F$100,'WP PROGRESS'!$C$2:$C$100,$A5),"")) | I5: =IF($A5="","",IFERROR(AVERAGEIFS('WP PROGRESS'!$G$2:$G$100,'WP PROGRESS'!$C$2:$C$100,$A5),"")) | J5: =IF($A5="","",IFERROR(AVERAGEIFS('WP PROGRESS'!$H$2:$H$100,'WP PROGRESS'!$C$2:$C$100,$A5),"")) | K5: =IF($A5="","",IFERROR(AVERAGEIFS('WP PROGRESS'!$I$2:$I$100,'WP PROGRESS'!$C$2:$C$100,$A5),"")) | L5: =IF($A5="","",IFERROR(AVERAGEIFS('WP PROGRESS'!$J$2:$J$100,'WP PROGRESS'!$C$2:$C$100,$A5),"")) | M5: =IF($A5="","",IFERROR(AVERAGEIFS('WP PROGRESS'!$K$2:$K$100,'WP PROGRESS'!$C$2:$C$100,$A5),"")) | N5: =IF(OR($A5="",C5=0),"",COUNTIFS('WP PROGRESS'!$C$2:$C$100,$A5,'WP PROGRESS'!$V$2:$V$100,"Yes")+COUNTIFS('WP PROGRESS'!$C$2:$C$100,$A5,'WP PROGRESS'!$V$2:$V$100,"--")&" of "&C5) | O5: =IF($A5="","",COUNTIFS('WP PROGRESS'!$C$2:$C$100,$A5,'WP PROGRESS'!$Y$2:$Y$100,"X"))
B6: =IF($A6="","",IFERROR(INDEX(SCOPES!$B$5:$B$200,MATCH($A6,SCOPES!$A$5:$A$200,0)),"")) | C6: =IF($A6="","",COUNTIF('WORK PACKAGES'!$G$2:$G$100,$A6)) | D6: =IF($A6="","",COUNTIFS(ISSUES!$O$5:$O$200,$A6,ISSUES!$H$5:$H$200,"<>Closed",ISSUES!$H$5:$H$200,"<>Resolved",ISSUES!$H$5:$H$200,"<>Cancelled",ISSUES!$H$5:$H$200,"<>",ISSUES!$A$5:$A$200,"<>")) | E6: =IF($A6="","",COUNTIFS('RFI REGISTER'!$F$5:$F$250,"*"&$A6&"*",'RFI REGISTER'!$C$5:$C$250,"<>Closed",'RFI REGISTER'!$C$5:$C$250,"<>Cancelled",'RFI REGISTER'!$C$5:$C$250,"<>",'RFI REGISTER'!$A$5:$A$250,"<>")) | G6: =IF($A6="","",IFERROR(INDEX(SCOPES!$K$5:$K$200,MATCH($A6,SCOPES!$A$5:$A$200,0)),"")) | H6: =IF($A6="","",IFERROR(AVERAGEIFS('WP PROGRESS'!$F$2:$F$100,'WP PROGRESS'!$C$2:$C$100,$A6),"")) | I6: =IF($A6="","",IFERROR(AVERAGEIFS('WP PROGRESS'!$G$2:$G$100,'WP PROGRESS'!$C$2:$C$100,$A6),"")) | J6: =IF($A6="","",IFERROR(AVERAGEIFS('WP PROGRESS'!$H$2:$H$100,'WP PROGRESS'!$C$2:$C$100,$A6),"")) | K6: =IF($A6="","",IFERROR(AVERAGEIFS('WP PROGRESS'!$I$2:$I$100,'WP PROGRESS'!$C$2:$C$100,$A6),"")) | L6: =IF($A6="","",IFERROR(AVERAGEIFS('WP PROGRESS'!$J$2:$J$100,'WP PROGRESS'!$C$2:$C$100,$A6),"")) | M6: =IF($A6="","",IFERROR(AVERAGEIFS('WP PROGRESS'!$K$2:$K$100,'WP PROGRESS'!$C$2:$C$100,$A6),"")) | N6: =IF(OR($A6="",C6=0),"",COUNTIFS('WP PROGRESS'!$C$2:$C$100,$A6,'WP PROGRESS'!$V$2:$V$100,"Yes")+COUNTIFS('WP PROGRESS'!$C$2:$C$100,$A6,'WP PROGRESS'!$V$2:$V$100,"--")&" of "&C6) | O6: =IF($A6="","",COUNTIFS('WP PROGRESS'!$C$2:$C$100,$A6,'WP PROGRESS'!$Y$2:$Y$100,"X"))
B7: =IF($A7="","",IFERROR(INDEX(SCOPES!$B$5:$B$200,MATCH($A7,SCOPES!$A$5:$A$200,0)),"")) | C7: =IF($A7="","",COUNTIF('WORK PACKAGES'!$G$2:$G$100,$A7)) | D7: =IF($A7="","",COUNTIFS(ISSUES!$O$5:$O$200,$A7,ISSUES!$H$5:$H$200,"<>Closed",ISSUES!$H$5:$H$200,"<>Resolved",ISSUES!$H$5:$H$200,"<>Cancelled",ISSUES!$H$5:$H$200,"<>",ISSUES!$A$5:$A$200,"<>")) | E7: =IF($A7="","",COUNTIFS('RFI REGISTER'!$F$5:$F$250,"*"&$A7&"*",'RFI REGISTER'!$C$5:$C$250,"<>Closed",'RFI REGISTER'!$C$5:$C$250,"<>Cancelled",'RFI REGISTER'!$C$5:$C$250,"<>",'RFI REGISTER'!$A$5:$A$250,"<>")) | G7: =IF($A7="","",IFERROR(INDEX(SCOPES!$K$5:$K$200,MATCH($A7,SCOPES!$A$5:$A$200,0)),"")) | H7: =IF($A7="","",IFERROR(AVERAGEIFS('WP PROGRESS'!$F$2:$F$100,'WP PROGRESS'!$C$2:$C$100,$A7),"")) | I7: =IF($A7="","",IFERROR(AVERAGEIFS('WP PROGRESS'!$G$2:$G$100,'WP PROGRESS'!$C$2:$C$100,$A7),"")) | J7: =IF($A7="","",IFERROR(AVERAGEIFS('WP PROGRESS'!$H$2:$H$100,'WP PROGRESS'!$C$2:$C$100,$A7),"")) | K7: =IF($A7="","",IFERROR(AVERAGEIFS('WP PROGRESS'!$I$2:$I$100,'WP PROGRESS'!$C$2:$C$100,$A7),"")) | L7: =IF($A7="","",IFERROR(AVERAGEIFS('WP PROGRESS'!$J$2:$J$100,'WP PROGRESS'!$C$2:$C$100,$A7),"")) | M7: =IF($A7="","",IFERROR(AVERAGEIFS('WP PROGRESS'!$K$2:$K$100,'WP PROGRESS'!$C$2:$C$100,$A7),"")) | N7: =IF(OR($A7="",C7=0),"",COUNTIFS('WP PROGRESS'!$C$2:$C$100,$A7,'WP PROGRESS'!$V$2:$V$100,"Yes")+COUNTIFS('WP PROGRESS'!$C$2:$C$100,$A7,'WP PROGRESS'!$V$2:$V$100,"--")&" of "&C7) | O7: =IF($A7="","",COUNTIFS('WP PROGRESS'!$C$2:$C$100,$A7,'WP PROGRESS'!$Y$2:$Y$100,"X"))
B8: =IF($A8="","",IFERROR(INDEX(SCOPES!$B$5:$B$200,MATCH($A8,SCOPES!$A$5:$A$200,0)),"")) | C8: =IF($A8="","",COUNTIF('WORK PACKAGES'!$G$2:$G$100,$A8)) | D8: =IF($A8="","",COUNTIFS(ISSUES!$O$5:$O$200,$A8,ISSUES!$H$5:$H$200,"<>Closed",ISSUES!$H$5:$H$200,"<>Resolved",ISSUES!$H$5:$H$200,"<>Cancelled",ISSUES!$H$5:$H$200,"<>",ISSUES!$A$5:$A$200,"<>")) | E8: =IF($A8="","",COUNTIFS('RFI REGISTER'!$F$5:$F$250,"*"&$A8&"*",'RFI REGISTER'!$C$5:$C$250,"<>Closed",'RFI REGISTER'!$C$5:$C$250,"<>Cancelled",'RFI REGISTER'!$C$5:$C$250,"<>",'RFI REGISTER'!$A$5:$A$250,"<>")) | G8: =IF($A8="","",IFERROR(INDEX(SCOPES!$K$5:$K$200,MATCH($A8,SCOPES!$A$5:$A$200,0)),"")) | H8: =IF($A8="","",IFERROR(AVERAGEIFS('WP PROGRESS'!$F$2:$F$100,'WP PROGRESS'!$C$2:$C$100,$A8),"")) | I8: =IF($A8="","",IFERROR(AVERAGEIFS('WP PROGRESS'!$G$2:$G$100,'WP PROGRESS'!$C$2:$C$100,$A8),"")) | J8: =IF($A8="","",IFERROR(AVERAGEIFS('WP PROGRESS'!$H$2:$H$100,'WP PROGRESS'!$C$2:$C$100,$A8),"")) | K8: =IF($A8="","",IFERROR(AVERAGEIFS('WP PROGRESS'!$I$2:$I$100,'WP PROGRESS'!$C$2:$C$100,$A8),"")) | L8: =IF($A8="","",IFERROR(AVERAGEIFS('WP PROGRESS'!$J$2:$J$100,'WP PROGRESS'!$C$2:$C$100,$A8),"")) | M8: =IF($A8="","",IFERROR(AVERAGEIFS('WP PROGRESS'!$K$2:$K$100,'WP PROGRESS'!$C$2:$C$100,$A8),"")) | N8: =IF(OR($A8="",C8=0),"",COUNTIFS('WP PROGRESS'!$C$2:$C$100,$A8,'WP PROGRESS'!$V$2:$V$100,"Yes")+COUNTIFS('WP PROGRESS'!$C$2:$C$100,$A8,'WP PROGRESS'!$V$2:$V$100,"--")&" of "&C8) | O8: =IF($A8="","",COUNTIFS('WP PROGRESS'!$C$2:$C$100,$A8,'WP PROGRESS'!$Y$2:$Y$100,"X"))
B9: =IF($A9="","",IFERROR(INDEX(SCOPES!$B$5:$B$200,MATCH($A9,SCOPES!$A$5:$A$200,0)),"")) | C9: =IF($A9="","",COUNTIF('WORK PACKAGES'!$G$2:$G$100,$A9)) | D9: =IF($A9="","",COUNTIFS(ISSUES!$O$5:$O$200,$A9,ISSUES!$H$5:$H$200,"<>Closed",ISSUES!$H$5:$H$200,"<>Resolved",ISSUES!$H$5:$H$200,"<>Cancelled",ISSUES!$H$5:$H$200,"<>",ISSUES!$A$5:$A$200,"<>")) | E9: =IF($A9="","",COUNTIFS('RFI REGISTER'!$F$5:$F$250,"*"&$A9&"*",'RFI REGISTER'!$C$5:$C$250,"<>Closed",'RFI REGISTER'!$C$5:$C$250,"<>Cancelled",'RFI REGISTER'!$C$5:$C$250,"<>",'RFI REGISTER'!$A$5:$A$250,"<>")) | G9: =IF($A9="","",IFERROR(INDEX(SCOPES!$K$5:$K$200,MATCH($A9,SCOPES!$A$5:$A$200,0)),"")) | H9: =IF($A9="","",IFERROR(AVERAGEIFS('WP PROGRESS'!$F$2:$F$100,'WP PROGRESS'!$C$2:$C$100,$A9),"")) | I9: =IF($A9="","",IFERROR(AVERAGEIFS('WP PROGRESS'!$G$2:$G$100,'WP PROGRESS'!$C$2:$C$100,$A9),"")) | J9: =IF($A9="","",IFERROR(AVERAGEIFS('WP PROGRESS'!$H$2:$H$100,'WP PROGRESS'!$C$2:$C$100,$A9),"")) | K9: =IF($A9="","",IFERROR(AVERAGEIFS('WP PROGRESS'!$I$2:$I$100,'WP PROGRESS'!$C$2:$C$100,$A9),"")) | L9: =IF($A9="","",IFERROR(AVERAGEIFS('WP PROGRESS'!$J$2:$J$100,'WP PROGRESS'!$C$2:$C$100,$A9),"")) | M9: =IF($A9="","",IFERROR(AVERAGEIFS('WP PROGRESS'!$K$2:$K$100,'WP PROGRESS'!$C$2:$C$100,$A9),"")) | N9: =IF(OR($A9="",C9=0),"",COUNTIFS('WP PROGRESS'!$C$2:$C$100,$A9,'WP PROGRESS'!$V$2:$V$100,"Yes")+COUNTIFS('WP PROGRESS'!$C$2:$C$100,$A9,'WP PROGRESS'!$V$2:$V$100,"--")&" of "&C9) | O9: =IF($A9="","",COUNTIFS('WP PROGRESS'!$C$2:$C$100,$A9,'WP PROGRESS'!$Y$2:$Y$100,"X"))
B10: =IF($A10="","",IFERROR(INDEX(SCOPES!$B$5:$B$200,MATCH($A10,SCOPES!$A$5:$A$200,0)),"")) | C10: =IF($A10="","",COUNTIF('WORK PACKAGES'!$G$2:$G$100,$A10)) | D10: =IF($A10="","",COUNTIFS(ISSUES!$O$5:$O$200,$A10,ISSUES!$H$5:$H$200,"<>Closed",ISSUES!$H$5:$H$200,"<>Resolved",ISSUES!$H$5:$H$200,"<>Cancelled",ISSUES!$H$5:$H$200,"<>",ISSUES!$A$5:$A$200,"<>")) | E10: =IF($A10="","",COUNTIFS('RFI REGISTER'!$F$5:$F$250,"*"&$A10&"*",'RFI REGISTER'!$C$5:$C$250,"<>Closed",'RFI REGISTER'!$C$5:$C$250,"<>Cancelled",'RFI REGISTER'!$C$5:$C$250,"<>",'RFI REGISTER'!$A$5:$A$250,"<>")) | G10: =IF($A10="","",IFERROR(INDEX(SCOPES!$K$5:$K$200,MATCH($A10,SCOPES!$A$5:$A$200,0)),"")) | H10: =IF($A10="","",IFERROR(AVERAGEIFS('WP PROGRESS'!$F$2:$F$100,'WP PROGRESS'!$C$2:$C$100,$A10),"")) | I10: =IF($A10="","",IFERROR(AVERAGEIFS('WP PROGRESS'!$G$2:$G$100,'WP PROGRESS'!$C$2:$C$100,$A10),"")) | J10: =IF($A10="","",IFERROR(AVERAGEIFS('WP PROGRESS'!$H$2:$H$100,'WP PROGRESS'!$C$2:$C$100,$A10),"")) | K10: =IF($A10="","",IFERROR(AVERAGEIFS('WP PROGRESS'!$I$2:$I$100,'WP PROGRESS'!$C$2:$C$100,$A10),"")) | L10: =IF($A10="","",IFERROR(AVERAGEIFS('WP PROGRESS'!$J$2:$J$100,'WP PROGRESS'!$C$2:$C$100,$A10),"")) | M10: =IF($A10="","",IFERROR(AVERAGEIFS('WP PROGRESS'!$K$2:$K$100,'WP PROGRESS'!$C$2:$C$100,$A10),"")) | N10: =IF(OR($A10="",C10=0),"",COUNTIFS('WP PROGRESS'!$C$2:$C$100,$A10,'WP PROGRESS'!$V$2:$V$100,"Yes")+COUNTIFS('WP PROGRESS'!$C$2:$C$100,$A10,'WP PROGRESS'!$V$2:$V$100,"--")&" of "&C10) | O10: =IF($A10="","",COUNTIFS('WP PROGRESS'!$C$2:$C$100,$A10,'WP PROGRESS'!$Y$2:$Y$100,"X"))
B11: =IF($A11="","",IFERROR(INDEX(SCOPES!$B$5:$B$200,MATCH($A11,SCOPES!$A$5:$A$200,0)),"")) | C11: =IF($A11="","",COUNTIF('WORK PACKAGES'!$G$2:$G$100,$A11)) | D11: =IF($A11="","",COUNTIFS(ISSUES!$O$5:$O$200,$A11,ISSUES!$H$5:$H$200,"<>Closed",ISSUES!$H$5:$H$200,"<>Resolved",ISSUES!$H$5:$H$200,"<>Cancelled",ISSUES!$H$5:$H$200,"<>",ISSUES!$A$5:$A$200,"<>")) | E11: =IF($A11="","",COUNTIFS('RFI REGISTER'!$F$5:$F$250,"*"&$A11&"*",'RFI REGISTER'!$C$5:$C$250,"<>Closed",'RFI REGISTER'!$C$5:$C$250,"<>Cancelled",'RFI REGISTER'!$C$5:$C$250,"<>",'RFI REGISTER'!$A$5:$A$250,"<>")) | G11: =IF($A11="","",IFERROR(INDEX(SCOPES!$K$5:$K$200,MATCH($A11,SCOPES!$A$5:$A$200,0)),"")) | H11: =IF($A11="","",IFERROR(AVERAGEIFS('WP PROGRESS'!$F$2:$F$100,'WP PROGRESS'!$C$2:$C$100,$A11),"")) | I11: =IF($A11="","",IFERROR(AVERAGEIFS('WP PROGRESS'!$G$2:$G$100,'WP PROGRESS'!$C$2:$C$100,$A11),"")) | J11: =IF($A11="","",IFERROR(AVERAGEIFS('WP PROGRESS'!$H$2:$H$100,'WP PROGRESS'!$C$2:$C$100,$A11),"")) | K11: =IF($A11="","",IFERROR(AVERAGEIFS('WP PROGRESS'!$I$2:$I$100,'WP PROGRESS'!$C$2:$C$100,$A11),"")) | L11: =IF($A11="","",IFERROR(AVERAGEIFS('WP PROGRESS'!$J$2:$J$100,'WP PROGRESS'!$C$2:$C$100,$A11),"")) | M11: =IF($A11="","",IFERROR(AVERAGEIFS('WP PROGRESS'!$K$2:$K$100,'WP PROGRESS'!$C$2:$C$100,$A11),"")) | N11: =IF(OR($A11="",C11=0),"",COUNTIFS('WP PROGRESS'!$C$2:$C$100,$A11,'WP PROGRESS'!$V$2:$V$100,"Yes")+COUNTIFS('WP PROGRESS'!$C$2:$C$100,$A11,'WP PROGRESS'!$V$2:$V$100,"--")&" of "&C11) | O11: =IF($A11="","",COUNTIFS('WP PROGRESS'!$C$2:$C$100,$A11,'WP PROGRESS'!$Y$2:$Y$100,"X"))
B12: =IF($A12="","",IFERROR(INDEX(SCOPES!$B$5:$B$200,MATCH($A12,SCOPES!$A$5:$A$200,0)),"")) | C12: =IF($A12="","",COUNTIF('WORK PACKAGES'!$G$2:$G$100,$A12)) | D12: =IF($A12="","",COUNTIFS(ISSUES!$O$5:$O$200,$A12,ISSUES!$H$5:$H$200,"<>Closed",ISSUES!$H$5:$H$200,"<>Resolved",ISSUES!$H$5:$H$200,"<>Cancelled",ISSUES!$H$5:$H$200,"<>",ISSUES!$A$5:$A$200,"<>")) | E12: =IF($A12="","",COUNTIFS('RFI REGISTER'!$F$5:$F$250,"*"&$A12&"*",'RFI REGISTER'!$C$5:$C$250,"<>Closed",'RFI REGISTER'!$C$5:$C$250,"<>Cancelled",'RFI REGISTER'!$C$5:$C$250,"<>",'RFI REGISTER'!$A$5:$A$250,"<>")) | G12: =IF($A12="","",IFERROR(INDEX(SCOPES!$K$5:$K$200,MATCH($A12,SCOPES!$A$5:$A$200,0)),"")) | H12: =IF($A12="","",IFERROR(AVERAGEIFS('WP PROGRESS'!$F$2:$F$100,'WP PROGRESS'!$C$2:$C$100,$A12),"")) | I12: =IF($A12="","",IFERROR(AVERAGEIFS('WP PROGRESS'!$G$2:$G$100,'WP PROGRESS'!$C$2:$C$100,$A12),"")) | J12: =IF($A12="","",IFERROR(AVERAGEIFS('WP PROGRESS'!$H$2:$H$100,'WP PROGRESS'!$C$2:$C$100,$A12),"")) | K12: =IF($A12="","",IFERROR(AVERAGEIFS('WP PROGRESS'!$I$2:$I$100,'WP PROGRESS'!$C$2:$C$100,$A12),"")) | L12: =IF($A12="","",IFERROR(AVERAGEIFS('WP PROGRESS'!$J$2:$J$100,'WP PROGRESS'!$C$2:$C$100,$A12),"")) | M12: =IF($A12="","",IFERROR(AVERAGEIFS('WP PROGRESS'!$K$2:$K$100,'WP PROGRESS'!$C$2:$C$100,$A12),"")) | N12: =IF(OR($A12="",C12=0),"",COUNTIFS('WP PROGRESS'!$C$2:$C$100,$A12,'WP PROGRESS'!$V$2:$V$100,"Yes")+COUNTIFS('WP PROGRESS'!$C$2:$C$100,$A12,'WP PROGRESS'!$V$2:$V$100,"--")&" of "&C12) | O12: =IF($A12="","",COUNTIFS('WP PROGRESS'!$C$2:$C$100,$A12,'WP PROGRESS'!$Y$2:$Y$100,"X"))
B13: =IF($A13="","",IFERROR(INDEX(SCOPES!$B$5:$B$200,MATCH($A13,SCOPES!$A$5:$A$200,0)),"")) | C13: =IF($A13="","",COUNTIF('WORK PACKAGES'!$G$2:$G$100,$A13)) | D13: =IF($A13="","",COUNTIFS(ISSUES!$O$5:$O$200,$A13,ISSUES!$H$5:$H$200,"<>Closed",ISSUES!$H$5:$H$200,"<>Resolved",ISSUES!$H$5:$H$200,"<>Cancelled",ISSUES!$H$5:$H$200,"<>",ISSUES!$A$5:$A$200,"<>")) | E13: =IF($A13="","",COUNTIFS('RFI REGISTER'!$F$5:$F$250,"*"&$A13&"*",'RFI REGISTER'!$C$5:$C$250,"<>Closed",'RFI REGISTER'!$C$5:$C$250,"<>Cancelled",'RFI REGISTER'!$C$5:$C$250,"<>",'RFI REGISTER'!$A$5:$A$250,"<>")) | G13: =IF($A13="","",IFERROR(INDEX(SCOPES!$K$5:$K$200,MATCH($A13,SCOPES!$A$5:$A$200,0)),"")) | H13: =IF($A13="","",IFERROR(AVERAGEIFS('WP PROGRESS'!$F$2:$F$100,'WP PROGRESS'!$C$2:$C$100,$A13),"")) | I13: =IF($A13="","",IFERROR(AVERAGEIFS('WP PROGRESS'!$G$2:$G$100,'WP PROGRESS'!$C$2:$C$100,$A13),"")) | J13: =IF($A13="","",IFERROR(AVERAGEIFS('WP PROGRESS'!$H$2:$H$100,'WP PROGRESS'!$C$2:$C$100,$A13),"")) | K13: =IF($A13="","",IFERROR(AVERAGEIFS('WP PROGRESS'!$I$2:$I$100,'WP PROGRESS'!$C$2:$C$100,$A13),"")) | L13: =IF($A13="","",IFERROR(AVERAGEIFS('WP PROGRESS'!$J$2:$J$100,'WP PROGRESS'!$C$2:$C$100,$A13),"")) | M13: =IF($A13="","",IFERROR(AVERAGEIFS('WP PROGRESS'!$K$2:$K$100,'WP PROGRESS'!$C$2:$C$100,$A13),"")) | N13: =IF(OR($A13="",C13=0),"",COUNTIFS('WP PROGRESS'!$C$2:$C$100,$A13,'WP PROGRESS'!$V$2:$V$100,"Yes")+COUNTIFS('WP PROGRESS'!$C$2:$C$100,$A13,'WP PROGRESS'!$V$2:$V$100,"--")&" of "&C13) | O13: =IF($A13="","",COUNTIFS('WP PROGRESS'!$C$2:$C$100,$A13,'WP PROGRESS'!$Y$2:$Y$100,"X"))
B14: =IF($A14="","",IFERROR(INDEX(SCOPES!$B$5:$B$200,MATCH($A14,SCOPES!$A$5:$A$200,0)),"")) | C14: =IF($A14="","",COUNTIF('WORK PACKAGES'!$G$2:$G$100,$A14)) | D14: =IF($A14="","",COUNTIFS(ISSUES!$O$5:$O$200,$A14,ISSUES!$H$5:$H$200,"<>Closed",ISSUES!$H$5:$H$200,"<>Resolved",ISSUES!$H$5:$H$200,"<>Cancelled",ISSUES!$H$5:$H$200,"<>",ISSUES!$A$5:$A$200,"<>")) | E14: =IF($A14="","",COUNTIFS('RFI REGISTER'!$F$5:$F$250,"*"&$A14&"*",'RFI REGISTER'!$C$5:$C$250,"<>Closed",'RFI REGISTER'!$C$5:$C$250,"<>Cancelled",'RFI REGISTER'!$C$5:$C$250,"<>",'RFI REGISTER'!$A$5:$A$250,"<>")) | G14: =IF($A14="","",IFERROR(INDEX(SCOPES!$K$5:$K$200,MATCH($A14,SCOPES!$A$5:$A$200,0)),"")) | H14: =IF($A14="","",IFERROR(AVERAGEIFS('WP PROGRESS'!$F$2:$F$100,'WP PROGRESS'!$C$2:$C$100,$A14),"")) | I14: =IF($A14="","",IFERROR(AVERAGEIFS('WP PROGRESS'!$G$2:$G$100,'WP PROGRESS'!$C$2:$C$100,$A14),"")) | J14: =IF($A14="","",IFERROR(AVERAGEIFS('WP PROGRESS'!$H$2:$H$100,'WP PROGRESS'!$C$2:$C$100,$A14),"")) | K14: =IF($A14="","",IFERROR(AVERAGEIFS('WP PROGRESS'!$I$2:$I$100,'WP PROGRESS'!$C$2:$C$100,$A14),"")) | L14: =IF($A14="","",IFERROR(AVERAGEIFS('WP PROGRESS'!$J$2:$J$100,'WP PROGRESS'!$C$2:$C$100,$A14),"")) | M14: =IF($A14="","",IFERROR(AVERAGEIFS('WP PROGRESS'!$K$2:$K$100,'WP PROGRESS'!$C$2:$C$100,$A14),"")) | N14: =IF(OR($A14="",C14=0),"",COUNTIFS('WP PROGRESS'!$C$2:$C$100,$A14,'WP PROGRESS'!$V$2:$V$100,"Yes")+COUNTIFS('WP PROGRESS'!$C$2:$C$100,$A14,'WP PROGRESS'!$V$2:$V$100,"--")&" of "&C14) | O14: =IF($A14="","",COUNTIFS('WP PROGRESS'!$C$2:$C$100,$A14,'WP PROGRESS'!$Y$2:$Y$100,"X"))
B15: =IF($A15="","",IFERROR(INDEX(SCOPES!$B$5:$B$200,MATCH($A15,SCOPES!$A$5:$A$200,0)),"")) | C15: =IF($A15="","",COUNTIF('WORK PACKAGES'!$G$2:$G$100,$A15)) | D15: =IF($A15="","",COUNTIFS(ISSUES!$O$5:$O$200,$A15,ISSUES!$H$5:$H$200,"<>Closed",ISSUES!$H$5:$H$200,"<>Resolved",ISSUES!$H$5:$H$200,"<>Cancelled",ISSUES!$H$5:$H$200,"<>",ISSUES!$A$5:$A$200,"<>")) | E15: =IF($A15="","",COUNTIFS('RFI REGISTER'!$F$5:$F$250,"*"&$A15&"*",'RFI REGISTER'!$C$5:$C$250,"<>Closed",'RFI REGISTER'!$C$5:$C$250,"<>Cancelled",'RFI REGISTER'!$C$5:$C$250,"<>",'RFI REGISTER'!$A$5:$A$250,"<>")) | G15: =IF($A15="","",IFERROR(INDEX(SCOPES!$K$5:$K$200,MATCH($A15,SCOPES!$A$5:$A$200,0)),"")) | H15: =IF($A15="","",IFERROR(AVERAGEIFS('WP PROGRESS'!$F$2:$F$100,'WP PROGRESS'!$C$2:$C$100,$A15),"")) | I15: =IF($A15="","",IFERROR(AVERAGEIFS('WP PROGRESS'!$G$2:$G$100,'WP PROGRESS'!$C$2:$C$100,$A15),"")) | J15: =IF($A15="","",IFERROR(AVERAGEIFS('WP PROGRESS'!$H$2:$H$100,'WP PROGRESS'!$C$2:$C$100,$A15),"")) | K15: =IF($A15="","",IFERROR(AVERAGEIFS('WP PROGRESS'!$I$2:$I$100,'WP PROGRESS'!$C$2:$C$100,$A15),"")) | L15: =IF($A15="","",IFERROR(AVERAGEIFS('WP PROGRESS'!$J$2:$J$100,'WP PROGRESS'!$C$2:$C$100,$A15),"")) | M15: =IF($A15="","",IFERROR(AVERAGEIFS('WP PROGRESS'!$K$2:$K$100,'WP PROGRESS'!$C$2:$C$100,$A15),"")) | N15: =IF(OR($A15="",C15=0),"",COUNTIFS('WP PROGRESS'!$C$2:$C$100,$A15,'WP PROGRESS'!$V$2:$V$100,"Yes")+COUNTIFS('WP PROGRESS'!$C$2:$C$100,$A15,'WP PROGRESS'!$V$2:$V$100,"--")&" of "&C15) | O15: =IF($A15="","",COUNTIFS('WP PROGRESS'!$C$2:$C$100,$A15,'WP PROGRESS'!$Y$2:$Y$100,"X"))
B16: =IF($A16="","",IFERROR(INDEX(SCOPES!$B$5:$B$200,MATCH($A16,SCOPES!$A$5:$A$200,0)),"")) | C16: =IF($A16="","",COUNTIF('WORK PACKAGES'!$G$2:$G$100,$A16)) | D16: =IF($A16="","",COUNTIFS(ISSUES!$O$5:$O$200,$A16,ISSUES!$H$5:$H$200,"<>Closed",ISSUES!$H$5:$H$200,"<>Resolved",ISSUES!$H$5:$H$200,"<>Cancelled",ISSUES!$H$5:$H$200,"<>",ISSUES!$A$5:$A$200,"<>")) | E16: =IF($A16="","",COUNTIFS('RFI REGISTER'!$F$5:$F$250,"*"&$A16&"*",'RFI REGISTER'!$C$5:$C$250,"<>Closed",'RFI REGISTER'!$C$5:$C$250,"<>Cancelled",'RFI REGISTER'!$C$5:$C$250,"<>",'RFI REGISTER'!$A$5:$A$250,"<>")) | G16: =IF($A16="","",IFERROR(INDEX(SCOPES!$K$5:$K$200,MATCH($A16,SCOPES!$A$5:$A$200,0)),"")) | H16: =IF($A16="","",IFERROR(AVERAGEIFS('WP PROGRESS'!$F$2:$F$100,'WP PROGRESS'!$C$2:$C$100,$A16),"")) | I16: =IF($A16="","",IFERROR(AVERAGEIFS('WP PROGRESS'!$G$2:$G$100,'WP PROGRESS'!$C$2:$C$100,$A16),"")) | J16: =IF($A16="","",IFERROR(AVERAGEIFS('WP PROGRESS'!$H$2:$H$100,'WP PROGRESS'!$C$2:$C$100,$A16),"")) | K16: =IF($A16="","",IFERROR(AVERAGEIFS('WP PROGRESS'!$I$2:$I$100,'WP PROGRESS'!$C$2:$C$100,$A16),"")) | L16: =IF($A16="","",IFERROR(AVERAGEIFS('WP PROGRESS'!$J$2:$J$100,'WP PROGRESS'!$C$2:$C$100,$A16),"")) | M16: =IF($A16="","",IFERROR(AVERAGEIFS('WP PROGRESS'!$K$2:$K$100,'WP PROGRESS'!$C$2:$C$100,$A16),"")) | N16: =IF(OR($A16="",C16=0),"",COUNTIFS('WP PROGRESS'!$C$2:$C$100,$A16,'WP PROGRESS'!$V$2:$V$100,"Yes")+COUNTIFS('WP PROGRESS'!$C$2:$C$100,$A16,'WP PROGRESS'!$V$2:$V$100,"--")&" of "&C16) | O16: =IF($A16="","",COUNTIFS('WP PROGRESS'!$C$2:$C$100,$A16,'WP PROGRESS'!$Y$2:$Y$100,"X"))
... B44: =IF($A44="","",IFERROR(INDEX(SCOPES!$B$5:$B$200,MATCH($A44,SCOPES!$A$5:$A$200,0)),"")) | C44: =IF($A44="","",COUNTIF('WORK PACKAGES'!$G$2:$G$100,$A44)) | D44: =IF($A44="","",COUNTIFS(ISSUES!$O$5:$O$200,$A44,ISSUES!$H$5:$H$200,"<>Closed",ISSUES!$H$5:$H$200,"<>Resolved",ISSUES!$H$5:$H$200,"<>Cancelled",ISSUES!$H$5:$H$200,"<>",ISSUES!$A$5:$A$200,"<>")) | E44: =IF($A44="","",COUNTIFS('RFI REGISTER'!$F$5:$F$250,"*"&$A44&"*",'RFI REGISTER'!$C$5:$C$250,"<>Closed",'RFI REGISTER'!$C$5:$C$250,"<>Cancelled",'RFI REGISTER'!$C$5:$C$250,"<>",'RFI REGISTER'!$A$5:$A$250,"<>")) | G44: =IF($A44="","",IFERROR(INDEX(SCOPES!$K$5:$K$200,MATCH($A44,SCOPES!$A$5:$A$200,0)),"")) | H44: =IF($A44="","",IFERROR(AVERAGEIFS('WP PROGRESS'!$F$2:$F$100,'WP PROGRESS'!$C$2:$C$100,$A44),"")) | I44: =IF($A44="","",IFERROR(AVERAGEIFS('WP PROGRESS'!$G$2:$G$100,'WP PROGRESS'!$C$2:$C$100,$A44),"")) | J44: =IF($A44="","",IFERROR(AVERAGEIFS('WP PROGRESS'!$H$2:$H$100,'WP PROGRESS'!$C$2:$C$100,$A44),"")) | K44: =IF($A44="","",IFERROR(AVERAGEIFS('WP PROGRESS'!$I$2:$I$100,'WP PROGRESS'!$C$2:$C$100,$A44),"")) | L44: =IF($A44="","",IFERROR(AVERAGEIFS('WP PROGRESS'!$J$2:$J$100,'WP PROGRESS'!$C$2:$C$100,$A44),"")) | M44: =IF($A44="","",IFERROR(AVERAGEIFS('WP PROGRESS'!$K$2:$K$100,'WP PROGRESS'!$C$2:$C$100,$A44),"")) | N44: =IF(OR($A44="",C44=0),"",COUNTIFS('WP PROGRESS'!$C$2:$C$100,$A44,'WP PROGRESS'!$V$2:$V$100,"Yes")+COUNTIFS('WP PROGRESS'!$C$2:$C$100,$A44,'WP PROGRESS'!$V$2:$V$100,"--")&" of "&C44) | O44: =IF($A44="","",COUNTIFS('WP PROGRESS'!$C$2:$C$100,$A44,'WP PROGRESS'!$Y$2:$Y$100,"X"))

Sheet WP PROGRESS
A1: Work Package ID | B1: Package Code | C1: Primary Scope ID | D1: Priority Sequence | E1: Open Punch Items | F1: Eng % Complete | G1: Prog % Complete | H1: Cond & Wire % Complete | I1: Device Install % Complete | J1: Loop Check % Complete | K1: PreComm % Complete | L1: C&E Values Received | M1: CE Target Test Date | N1: Engineering Completed? | O1: Programming Completed? | P1: Cond & Wire Completed? | Q1: Device Install Completed | R1: Loops Check Completed | S1: PreComm Complete? | T1: Program Changes Required | U1: Program changes Completed | V1: Internal Progress Gates Complete? | W1: Site Acceptance Test Complete? | X1: Vendor Completed Checks | Y1: Blocked? (X) | Z1: Open RFIs | AA1: Open Engineering Issues | AB1: Progress Comments | AC1: Row Check (derived)
B2: =IF($A2="","",IFERROR(IF(INDEX('WORK PACKAGES'!$B$2:$B$100,MATCH($A2,'WORK PACKAGES'!$A$2:$A$100,0))="","",INDEX('WORK PACKAGES'!$B$2:$B$100,MATCH($A2,'WORK PACKAGES'!$A$2:$A$100,0))),"")) | C2: =IF($A2="","",IFERROR(IF(INDEX('WORK PACKAGES'!$G$2:$G$100,MATCH($A2,'WORK PACKAGES'!$A$2:$A$100,0))="","",INDEX('WORK PACKAGES'!$G$2:$G$100,MATCH($A2,'WORK PACKAGES'!$A$2:$A$100,0))),"")) | D2: =IF($A2="","",IFERROR(IF(INDEX('WORK PACKAGES'!$E$2:$E$100,MATCH($A2,'WORK PACKAGES'!$A$2:$A$100,0))="","",INDEX('WORK PACKAGES'!$E$2:$E$100,MATCH($A2,'WORK PACKAGES'!$A$2:$A$100,0))),"")) | E2: =IF(A2="","",IF(COUNTIFS('PUNCH LIST'!$G$3:$G$464,A2,'PUNCH LIST'!$Q$3:$Q$464,"Open")=0,"",COUNTIFS('PUNCH LIST'!$G$3:$G$464,A2,'PUNCH LIST'!$Q$3:$Q$464,"Open"))) | N2: =IF($A2="","",IF(ISBLANK(F2),"",IF(TRIM(F2)="--","--",IF(ISNUMBER(F2),IF(F2>=1,"Yes",IF(F2=0,"No","PARTIAL")),"CHECK")))) | O2: =IF($A2="","",IF(ISBLANK(G2),"",IF(TRIM(G2)="--","--",IF(ISNUMBER(G2),IF(G2>=1,"Yes",IF(G2=0,"No","PARTIAL")),"CHECK")))) | P2: =IF($A2="","",IF(ISBLANK(H2),"",IF(TRIM(H2)="--","--",IF(ISNUMBER(H2),IF(H2>=1,"Yes",IF(H2=0,"No","PARTIAL")),"CHECK")))) | Q2: =IF($A2="","",IF(ISBLANK(I2),"",IF(TRIM(I2)="--","--",IF(ISNUMBER(I2),IF(I2>=1,"Yes",IF(I2=0,"No","PARTIAL")),"CHECK")))) | R2: =IF($A2="","",IF(ISBLANK(J2),"",IF(TRIM(J2)="--","--",IF(ISNUMBER(J2),IF(J2>=1,"Yes",IF(J2=0,"No","PARTIAL")),"CHECK")))) | S2: =IF($A2="","",IF(ISBLANK(K2),"",IF(TRIM(K2)="--","--",IF(ISNUMBER(K2),IF(K2>=1,"Yes",IF(K2=0,"No","PARTIAL")),"CHECK")))) | V2: =IF($A2="","",IF(COUNTIF(N2:S2,"--")=6,"--",IF(COUNTIF(N2:S2,"Yes")+COUNTIF(N2:S2,"--")=6,"Yes","No"))) | Z2: =IF($A2="","",COUNTIFS('RFI REGISTER'!$D$5:$D$250,$A2,'RFI REGISTER'!$A$5:$A$250,"RFI-*",'RFI REGISTER'!$C$5:$C$250,"<>Closed",'RFI REGISTER'!$C$5:$C$250,"<>Cancelled")) | AA2: =IF($A2="","",COUNTIFS(ISSUES!$P$5:$P$200,"*"&$A2&"*",ISSUES!$H$5:$H$200,"<>Closed",ISSUES!$H$5:$H$200,"<>Resolved",ISSUES!$H$5:$H$200,"<>Cancelled",ISSUES!$H$5:$H$200,"<>",ISSUES!$A$5:$A$200,"<>")) | AC2: =IF(A2="","",IF(COUNTIF('WORK PACKAGES'!$A$2:$A$100,A2)=0,"NOT IN WORK PACKAGES",IF(COUNTIF($A$2:$A$100,A2)>1,"DUPLICATE","OK")))
B3: =IF($A3="","",IFERROR(IF(INDEX('WORK PACKAGES'!$B$2:$B$100,MATCH($A3,'WORK PACKAGES'!$A$2:$A$100,0))="","",INDEX('WORK PACKAGES'!$B$2:$B$100,MATCH($A3,'WORK PACKAGES'!$A$2:$A$100,0))),"")) | C3: =IF($A3="","",IFERROR(IF(INDEX('WORK PACKAGES'!$G$2:$G$100,MATCH($A3,'WORK PACKAGES'!$A$2:$A$100,0))="","",INDEX('WORK PACKAGES'!$G$2:$G$100,MATCH($A3,'WORK PACKAGES'!$A$2:$A$100,0))),"")) | D3: =IF($A3="","",IFERROR(IF(INDEX('WORK PACKAGES'!$E$2:$E$100,MATCH($A3,'WORK PACKAGES'!$A$2:$A$100,0))="","",INDEX('WORK PACKAGES'!$E$2:$E$100,MATCH($A3,'WORK PACKAGES'!$A$2:$A$100,0))),"")) | E3: =IF(A3="","",IF(COUNTIFS('PUNCH LIST'!$G$3:$G$464,A3,'PUNCH LIST'!$Q$3:$Q$464,"Open")=0,"",COUNTIFS('PUNCH LIST'!$G$3:$G$464,A3,'PUNCH LIST'!$Q$3:$Q$464,"Open"))) | N3: =IF($A3="","",IF(ISBLANK(F3),"",IF(TRIM(F3)="--","--",IF(ISNUMBER(F3),IF(F3>=1,"Yes",IF(F3=0,"No","PARTIAL")),"CHECK")))) | O3: =IF($A3="","",IF(ISBLANK(G3),"",IF(TRIM(G3)="--","--",IF(ISNUMBER(G3),IF(G3>=1,"Yes",IF(G3=0,"No","PARTIAL")),"CHECK")))) | P3: =IF($A3="","",IF(ISBLANK(H3),"",IF(TRIM(H3)="--","--",IF(ISNUMBER(H3),IF(H3>=1,"Yes",IF(H3=0,"No","PARTIAL")),"CHECK")))) | Q3: =IF($A3="","",IF(ISBLANK(I3),"",IF(TRIM(I3)="--","--",IF(ISNUMBER(I3),IF(I3>=1,"Yes",IF(I3=0,"No","PARTIAL")),"CHECK")))) | R3: =IF($A3="","",IF(ISBLANK(J3),"",IF(TRIM(J3)="--","--",IF(ISNUMBER(J3),IF(J3>=1,"Yes",IF(J3=0,"No","PARTIAL")),"CHECK")))) | S3: =IF($A3="","",IF(ISBLANK(K3),"",IF(TRIM(K3)="--","--",IF(ISNUMBER(K3),IF(K3>=1,"Yes",IF(K3=0,"No","PARTIAL")),"CHECK")))) | V3: =IF($A3="","",IF(COUNTIF(N3:S3,"--")=6,"--",IF(COUNTIF(N3:S3,"Yes")+COUNTIF(N3:S3,"--")=6,"Yes","No"))) | Z3: =IF($A3="","",COUNTIFS('RFI REGISTER'!$D$5:$D$250,$A3,'RFI REGISTER'!$A$5:$A$250,"RFI-*",'RFI REGISTER'!$C$5:$C$250,"<>Closed",'RFI REGISTER'!$C$5:$C$250,"<>Cancelled")) | AA3: =IF($A3="","",COUNTIFS(ISSUES!$P$5:$P$200,"*"&$A3&"*",ISSUES!$H$5:$H$200,"<>Closed",ISSUES!$H$5:$H$200,"<>Resolved",ISSUES!$H$5:$H$200,"<>Cancelled",ISSUES!$H$5:$H$200,"<>",ISSUES!$A$5:$A$200,"<>")) | AC3: =IF(A3="","",IF(COUNTIF('WORK PACKAGES'!$A$2:$A$100,A3)=0,"NOT IN WORK PACKAGES",IF(COUNTIF($A$2:$A$100,A3)>1,"DUPLICATE","OK")))
B4: =IF($A4="","",IFERROR(IF(INDEX('WORK PACKAGES'!$B$2:$B$100,MATCH($A4,'WORK PACKAGES'!$A$2:$A$100,0))="","",INDEX('WORK PACKAGES'!$B$2:$B$100,MATCH($A4,'WORK PACKAGES'!$A$2:$A$100,0))),"")) | C4: =IF($A4="","",IFERROR(IF(INDEX('WORK PACKAGES'!$G$2:$G$100,MATCH($A4,'WORK PACKAGES'!$A$2:$A$100,0))="","",INDEX('WORK PACKAGES'!$G$2:$G$100,MATCH($A4,'WORK PACKAGES'!$A$2:$A$100,0))),"")) | D4: =IF($A4="","",IFERROR(IF(INDEX('WORK PACKAGES'!$E$2:$E$100,MATCH($A4,'WORK PACKAGES'!$A$2:$A$100,0))="","",INDEX('WORK PACKAGES'!$E$2:$E$100,MATCH($A4,'WORK PACKAGES'!$A$2:$A$100,0))),"")) | E4: =IF(A4="","",IF(COUNTIFS('PUNCH LIST'!$G$3:$G$464,A4,'PUNCH LIST'!$Q$3:$Q$464,"Open")=0,"",COUNTIFS('PUNCH LIST'!$G$3:$G$464,A4,'PUNCH LIST'!$Q$3:$Q$464,"Open"))) | N4: =IF($A4="","",IF(ISBLANK(F4),"",IF(TRIM(F4)="--","--",IF(ISNUMBER(F4),IF(F4>=1,"Yes",IF(F4=0,"No","PARTIAL")),"CHECK")))) | O4: =IF($A4="","",IF(ISBLANK(G4),"",IF(TRIM(G4)="--","--",IF(ISNUMBER(G4),IF(G4>=1,"Yes",IF(G4=0,"No","PARTIAL")),"CHECK")))) | P4: =IF($A4="","",IF(ISBLANK(H4),"",IF(TRIM(H4)="--","--",IF(ISNUMBER(H4),IF(H4>=1,"Yes",IF(H4=0,"No","PARTIAL")),"CHECK")))) | Q4: =IF($A4="","",IF(ISBLANK(I4),"",IF(TRIM(I4)="--","--",IF(ISNUMBER(I4),IF(I4>=1,"Yes",IF(I4=0,"No","PARTIAL")),"CHECK")))) | R4: =IF($A4="","",IF(ISBLANK(J4),"",IF(TRIM(J4)="--","--",IF(ISNUMBER(J4),IF(J4>=1,"Yes",IF(J4=0,"No","PARTIAL")),"CHECK")))) | S4: =IF($A4="","",IF(ISBLANK(K4),"",IF(TRIM(K4)="--","--",IF(ISNUMBER(K4),IF(K4>=1,"Yes",IF(K4=0,"No","PARTIAL")),"CHECK")))) | V4: =IF($A4="","",IF(COUNTIF(N4:S4,"--")=6,"--",IF(COUNTIF(N4:S4,"Yes")+COUNTIF(N4:S4,"--")=6,"Yes","No"))) | Z4: =IF($A4="","",COUNTIFS('RFI REGISTER'!$D$5:$D$250,$A4,'RFI REGISTER'!$A$5:$A$250,"RFI-*",'RFI REGISTER'!$C$5:$C$250,"<>Closed",'RFI REGISTER'!$C$5:$C$250,"<>Cancelled")) | AA4: =IF($A4="","",COUNTIFS(ISSUES!$P$5:$P$200,"*"&$A4&"*",ISSUES!$H$5:$H$200,"<>Closed",ISSUES!$H$5:$H$200,"<>Resolved",ISSUES!$H$5:$H$200,"<>Cancelled",ISSUES!$H$5:$H$200,"<>",ISSUES!$A$5:$A$200,"<>")) | AC4: =IF(A4="","",IF(COUNTIF('WORK PACKAGES'!$A$2:$A$100,A4)=0,"NOT IN WORK PACKAGES",IF(COUNTIF($A$2:$A$100,A4)>1,"DUPLICATE","OK")))
